Workbook
Name _DLX1.USE: #REF!
Name _DLX10.USE: #REF!
Name _DLX2.USE: #REF!
Name _DLX3.USE: #REF!
Name _DLX4.USE: #REF!
Name _DLX5.USE: #REF!
Name _DLX6.USE: #REF!
Name _DLX8.USE: #REF!
Name aaddr: #REF!
Name AdjustedBCA: [14]Prog!$R$25
Name AdjustedBCAIssuer: [14]Prog!$R$14
Name AdjustedBCAParent: [14]Prog!$R$18
Name annual: #REF!
Name ASheet: #REF!
Name AUS_BANK_AUSTRIA: #REF!
Name AUS_ERSTE: #REF!
Name AUS_RAIFF: #REF!
Name CBRatingOutlook: [14]Prog!$R$22
Name ChartData: [19]Rate_expectations_data_old!$A$9:$AP$5000
Name Chartdata_new: [19]Rate_expectations_data!$A$9:$GD$5000
Name CollateralScoreBlendedState: [14]Prog!$T$30
Name CollateralScoreBlendedValue: [14]Prog!$R$30
Name CollateralScoreExcludingSystemicRiskState: [14]Prog!$T$31
Name CollateralScoreExcludingSystemicRiskValue: [14]Prog!$R$31
Name CollateralTypeMain: [14]Prog!$R$19
Name CommercialRelative: [14]Prog!$AC$4
Name COMMODITIES: #REF!
Name Consensus: Priv [20]Con!$A$12
Name Consensus: Priv [20]Con!$A$12
Name Consensus: Priv [20]Con!$A$12
Name Consensus: Priv [20]Con!$A$12
Name Contact: [14]Prog!$R$4
Name CoveredBondAnchor: [14]Prog!$R$26
Name CurrentOCState: [14]Prog!$T$41
Name CurrentOCValue: [14]Prog!$R$41
Name Cutoff_date: [21]Evaluation!$O$3
Name CutoffDate: [14]Prog!$R$6
Name data1: [19]CDS_data!$AJ$6:$AO$1120
Name Data2: #REF!
Name data3: [22]data!$S$6:$X$1120
Name data4: #REF!
Name DebtCushion: [14]Prog!$R$27
Name DefaultCurrency: [14]Prog!$R$8
Name ESP_BBVA: #REF!
Name ESP_POPULAR: #REF!
Name ESP_SANTANDER: #REF!
Name EurLiborCurve: '[19]Euro LIBOR Curve Data'!$A$7:$J$2000
Name Eurliborcurve_new: #REF!
Name FixedRateAssetsInCoverPoolValue: [14]Prog!$R$55
Name FixedRateCoveredBondsOutstandingValue: [14]Prog!$R$56
Name FRA_BNP: #REF!
Name FRA_CA: #REF!
Name FRA_NATIXIS: #REF!
Name FRA_SG: #REF!
Name GVal: #REF!
Name High: Priv [20]Con!$A$112
Name High: Priv [20]Con!$A$112
Name High: Priv [20]Con!$A$112
Name High: Priv [20]Con!$A$112
Name InterestRateSwapProvider: [14]Prog!$R$60

Sheet ICS_A-IRB
B3: Capital Charge - Credit Risk (ICS - based on Basel III, Internal Ratings-Based Approach) | N3: 0 | O3: Moody's Aaa | S3: 1 | T3: Moody's Aa | X3: 2 | Y3: Moody's A | AC3: 3 | AD3: Moody's Baa | AH3: 4 | AI3: Moody's Ba | AM3: 5 | AN3: Moody's B | AT3: Unrated | AU3: Moody's project loan database (total sample)
B4: (In percent) | N4: PD | O4: Correlation (R) [depends on PD] | P4: Maturity adj. (M) [depends on PD] | Q4: Cap. Requirement (K) | S4: PD | T4: Correlation (R) [depends on PD] | U4: Maturity adj. (M) [depends on PD] | V4: Cap. Requirement (K) | X4: PD | Y4: Correlation (R) [depends on PD] | Z4: Maturity adj. (M) [depends on PD] | AA4: Cap. Requirement (K) | AC4: PD | AD4: Correlation (R) [depends on PD] | AE4: Maturity adj. (M) [depends on PD] | AF4: Cap. Requirement (K) | AH4: PD | AI4: Correlation (R) [depends on PD] | AJ4: Maturity adj. (M) [depends on PD] | AK4: Cap. Requirement (K) | AM4: PD | AN4: Correlation (R) [depends on PD] | AO4: Maturity adj. (M) [depends on PD] | AP4: Cap. Requirement (K) | AT4: PD | AU4: Correlation (R) [depends on PD] | AV4: Maturity adj. (M) [depends on PD] | AW4: Cap. Requirement (K)
D5: Credit Quality Step (CQS)
B6: Maturity (Years) | D6: ='[2]EIOPA - Nongreen'!D22 -> 0 | E6: ='[2]EIOPA - Nongreen'!F22 -> 1 | F6: ='[2]EIOPA - Nongreen'!H22 -> 2 | G6: ='[2]EIOPA - Nongreen'!J22 -> 3 | H6: ='[2]EIOPA - Nongreen'!L22 -> 4 | I6: 5 | K6: ='[2]EIOPA - Nongreen'!R22 -> Unrated | N6: LGD | S6: LGD | X6: LGD | AC6: LGD | AH6: LGD | AM6: LGD | AT6: LGD
D8: Corporate Exposures - Non-financial Corporate Debt Securities - Global | N8: =1-'[2]Moody''s Global Infra and Corp D'!P103 -> 0.62 | S8: =N8 -> 0.62 | X8: =N8 -> 0.62 | AC8: =X8 -> 0.62 | AH8: =X8 -> 0.62 | AM8: =AC8 -> 0.62 | AN8: stdev(rec.) | AO8: ='[2]Moody''s Global Infra and Corp D'!K138 -> 0.337 | AP8: =AO8*(AM8/(1-AM8)) -> 0.54984211
B9: 1 | D9: =Q9*100 -> 0.049015661 | E9: =V9*100 -> 0.049015661 | F9: =AA9*100 -> 0.60703136 | G9: =AF9*100 -> 2.4747913 | H9: =AK9*100 -> 8.0059045 | I9: =AP9*100 -> 17.537063 | K9: =H9 -> 8.0059045 | N9: ='[2]Moody''s Global Infra and Corp D'!$AN$61 -> 1e-05 | O9: =0.12*(1-EXP(-50*$N9))/(1-EXP(-50))+0.24*(1-(1-EXP(-50*$N9))/(1-EXP(-50))) -> 0.23994001 | P9: =(0.11852-0.05478*LN($N9))^2 -> 0.56129773 | Q9: =(N$8*NORMSDIST((1-O9)^(-0.5)*NORMSINV($N9)+(O9/(1-O9))^(0.5)*NORMSINV(0.999))-$N9*N$8)*((1+($B9-2.5)*P9)/(1-1.5*P9)) -> 0.00049015661 | S9: ='[2]Moody''s Global Infra and Corp D'!$AN$62 -> 1e-05 | T9: =0.12*(1-EXP(-50*$S9))/(1-EXP(-50))+0.24*(1-(1-EXP(-50*$S9))/(1-EXP(-50))) -> 0.23994001 | U9: =(0.11852-0.05478*LN($S9))^2 -> 0.56129773 | V9: =(S$8*NORMSDIST((1-T9)^(-0.5)*NORMSINV($S9)+(T9/(1-T9))^(0.5)*NORMSINV(0.999))-$S9*S$8)*((1+($B9-2.5)*U9)/(1-1.5*U9)) -> 0.00049015661 | X9: ='[2]Moody''s Global Infra and Corp D'!$AN$63 -> 0.0002 | Y9: =0.12*(1-EXP(-50*$X9))/(1-EXP(-50))+0.24*(1-(1-EXP(-50*$X9))/(1-EXP(-50))) -> 0.23880598 | Z9: =(0.11852-0.05478*LN($X9))^2 -> 0.34233246 | AA9: =(X$8*NORMSDIST((1-Y9)^(-0.5)*NORMSINV($X9)+(Y9/(1-Y9))^(0.5)*NORMSINV(0.999))-$X9*X$8)*((1+($B9-2.5)*Z9)/(1-1.5*Z9)) -> 0.0060703136 | AB9: =AC9 -> 0.0013 | AC9: ='[2]Moody''s Global Infra and Corp D'!$AN$64 -> 0.0013 | AD9: =0.12*(1-EXP(-50*$AC9))/(1-EXP(-50))+0.24*(1-(1-EXP(-50*$AC9))/(1-EXP(-50))) -> 0.2324481 | AE9: =(0.11852-0.05478*LN($AC9))^2 -> 0.23285886 | AF9: =(AC$8*NORMSDIST((1-AD9)^(-0.5)*NORMSINV($AC9)+(AD9/(1-AD9))^(0.5)*NORMSINV(0.999))-$AC9*AC$8)*((1+($B9-2.5)*AE9)/(1-1.5*AE9)) -> 0.024747913 | AG9: =AH9 -> 0.0098 | AH9: ='[2]Moody''s Global Infra and Corp D'!$AN$65 -> 0.0098 | AI9: =0.12*(1-EXP(-50*$AH9))/(1-EXP(-50))+0.24*(1-(1-EXP(-50*$AH9))/(1-EXP(-50))) -> 0.19351517 | AJ9: =(0.11852-0.05478*LN($AH9))^2 -> 0.13830807 | AK9: =(AH$8*NORMSDIST((1-AI9)^(-0.5)*NORMSINV($AH9)+(AI9/(1-AI9))^(0.5)*NORMSINV(0.999))-$AH9*AH$8)*((1+($B9-2.5)*AJ9)/(1-1.5*AJ9)) -> 0.080059045 | AL9: =MAX(AM9,0.005) -> 0.0377 | AM9: ='[2]Moody''s Global Infra and Corp D'!$AN$66 -> 0.0377 | AN9: =0.12*(1-EXP(-50*$AH9))/(1-EXP(-50))+0.24*(1-(1-EXP(-50*$AH9))/(1-EXP(-50))) -> 0.19351517 | AO9: =(0.11852-0.05478*LN($AM9))^2 -> 0.088860065 | AP9: =(AM$8*NORMSDIST((1-AN9)^(-0.5)*NORMSINV($AM9)+(AN9/(1-AN9))^(0.5)*NORMSINV(0.999))-$AM9*AM$8)*((1+($B9-2.5)*AO9)/(1-1.5*AO9)) -> 0.17537063
B10: 2 | D10: =Q10*100 -> 0.22308581 | E10: =V10*100 -> 0.66907318 | F10: =AA10*100 -> 2.8649698 | G10: =AF10*100 -> 5.9695899 | H10: =AK10*100 -> 13.188898 | I10: =AP10*100 -> 23.109241 | K10: =H10 -> 13.188898 | N10: ='[2]Moody''s Global Infra and Corp D'!$AO$61 -> 1e-05 | O10: =0.12*(1-EXP(-50*$N10))/(1-EXP(-50))+0.24*(1-(1-EXP(-50*$N10))/(1-EXP(-50))) -> 0.23994001 | P10: =(0.11852-0.05478*LN($N10))^2 -> 0.56129773 | Q10: =(N$8*NORMSDIST((1-O10)^(-0.5)*NORMSINV($N10)+(O10/(1-O10))^(0.5)*NORMSINV(0.999))-$N10*N$8)*((1+($B10-2.5)*P10)/(1-1.5*P10)) -> 0.0022308581 | S10: ='[2]Moody''s Global Infra and Corp D'!$AO$62 -> 0.0001 | T10: =0.12*(1-EXP(-50*$S10))/(1-EXP(-50))+0.24*(1-(1-EXP(-50*$S10))/(1-EXP(-50))) -> 0.2394015 | U10: =(0.11852-0.05478*LN($S10))^2 -> 0.38820681 | V10: =(S$8*NORMSDIST((1-T10)^(-0.5)*NORMSINV($S10)+(T10/(1-T10))^(0.5)*NORMSINV(0.999))-$S10*S$8)*((1+($B10-2.5)*U10)/(1-1.5*U10)) -> 0.0066907318 | X10: ='[2]Moody''s Global Infra and Corp D'!$AO$63 -> 0.001 | Y10: =0.12*(1-EXP(-50*$X10))/(1-EXP(-50))+0.24*(1-(1-EXP(-50*$X10))/(1-EXP(-50))) -> 0.23414753 | Z10: =(0.11852-0.05478*LN($X10))^2 -> 0.24693628 | AA10: =(X$8*NORMSDIST((1-Y10)^(-0.5)*NORMSINV($X10)+(Y10/(1-Y10))^(0.5)*NORMSINV(0.999))-$X10*X$8)*((1+($B10-2.5)*Z10)/(1-1.5*Z10)) -> 0.028649698 | AB10: =MAX(AC10-AC9,0) -> 0.0023 | AC10: ='[2]Moody''s Global Infra and Corp D'!$AO$64 -> 0.0036 | AD10: =0.12*(1-EXP(-50*$AC10))/(1-EXP(-50))+0.24*(1-(1-EXP(-50*$AC10))/(1-EXP(-50))) -> 0.22023243 | AE10: =(0.11852-0.05478*LN($AC10))^2 -> 0.18212177 | AF10: =(AC$8*NORMSDIST((1-AD10)^(-0.5)*NORMSINV($AC10)+(AD10/(1-AD10))^(0.5)*NORMSINV(0.999))-$AC10*AC$8)*((1+($B10-2.5)*AE10)/(1-1.5*AE10)) -> 0.059695899 | AG10: =MAX(AH10-AH9,0) -> 0.0181 | AH10: ='[2]Moody''s Global Infra and Corp D'!$AO$65 -> 0.0279 | AI10: =0.12*(1-EXP(-50*$AH10))/(1-EXP(-50))+0.24*(1-(1-EXP(-50*$AH10))/(1-EXP(-50))) -> 0.14973996 | AJ10: =(0.11852-0.05478*LN($AH10))^2 -> 0.098963511 | AK10: =(AH$8*NORMSDIST((1-AI10)^(-0.5)*NORMSINV($AH10)+(AI10/(1-AI10))^(0.5)*NORMSINV(0.999))-$AH10*AH$8)*((1+($B10-2.5)*AJ10)/(1-1.5*AJ10)) -> 0.13188898 | AL10: =MAX(AM10-AM9,0.005) -> 0.053 | AM10: ='[2]Moody''s Global Infra and Corp D'!$AO$66 -> 0.0907 | AN10: =0.12*(1-EXP(-50*$AH10))/(1-EXP(-50))+0.24*(1-(1-EXP(-50*$AH10))/(1-EXP(-50))) -> 0.14973996 | AO10: =(0.11852-0.05478*LN($AM10))^2 -> 0.062501421 | AP10: =(AM$8*NORMSDIST((1-AN10)^(-0.5)*NORMSINV($AM10)+(AN10/(1-AN10))^(0.5)*NORMSINV(0.999))-$AM10*AM$8)*((1+($B10-2.5)*AO10)/(1-1.5*AO10)) -> 0.23109241
B11: 3 | D11: =Q11*100 -> 0.39715595 | E11: =V11*100 -> 1.8442026 | F11: =AA11*100 -> 5.7482172 | G11: =AF11*100 -> 9.2164456 | H11: =AK11*100 -> 17.209803 | I11: =AP11*100 -> 26.036047 | K11: =H11 -> 17.209803 | N11: ='[2]Moody''s Global Infra and Corp D'!$AP$61 -> 1e-05 | O11: =0.12*(1-EXP(-50*$N11))/(1-EXP(-50))+0.24*(1-(1-EXP(-50*$N11))/(1-EXP(-50))) -> 0.23994001 | P11: =(0.11852-0.05478*LN($N11))^2 -> 0.56129773 | Q11: =(N$8*NORMSDIST((1-O11)^(-0.5)*NORMSINV($N11)+(O11/(1-O11))^(0.5)*NORMSINV(0.999))-$N11*N$8)*((1+($B11-2.5)*P11)/(1-1.5*P11)) -> 0.0039715595 | S11: ='[2]Moody''s Global Infra and Corp D'!$AP$62 -> 0.0003 | T11: =0.12*(1-EXP(-50*$S11))/(1-EXP(-50))+0.24*(1-(1-EXP(-50*$S11))/(1-EXP(-50))) -> 0.23821343 | U11: =(0.11852-0.05478*LN($S11))^2 -> 0.31683442 | V11: =(S$8*NORMSDIST((1-T11)^(-0.5)*NORMSINV($S11)+(T11/(1-T11))^(0.5)*NORMSINV(0.999))-$S11*S$8)*((1+($B11-2.5)*U11)/(1-1.5*U11)) -> 0.018442026 | X11: ='[2]Moody''s Global Infra and Corp D'!$AP$63 -> 0.0023 | Y11: =0.12*(1-EXP(-50*$X11))/(1-EXP(-50))+0.24*(1-(1-EXP(-50*$X11))/(1-EXP(-50))) -> 0.22696394 | Z11: =(0.11852-0.05478*LN($X11))^2 -> 0.20367176 | AA11: =(X$8*NORMSDIST((1-Y11)^(-0.5)*NORMSINV($X11)+(Y11/(1-Y11))^(0.5)*NORMSINV(0.999))-$X11*X$8)*((1+($B11-2.5)*Z11)/(1-1.5*Z11)) -> 0.057482172 | AB11: =MAX(AC11-AC10,0) -> 0.0028 | AC11: ='[2]Moody''s Global Infra and Corp D'!$AP$64 -> 0.0064 | AD11: =0.12*(1-EXP(-50*$AC11))/(1-EXP(-50))+0.24*(1-(1-EXP(-50*$AC11))/(1-EXP(-50))) -> 0.20713788 | AE11: =(0.11852-0.05478*LN($AC11))^2 -> 0.15621373 | AF11: =(AC$8*NORMSDIST((1-AD11)^(-0.5)*NORMSINV($AC11)+(AD11/(1-AD11))^(0.5)*NORMSINV(0.999))-$AC11*AC$8)*((1+($B11-2.5)*AE11)/(1-1.5*AE11)) -> 0.092164456 | AG11: =MAX(AH11-AH10,0) -> 0.0224 | AH11: ='[2]Moody''s Global Infra and Corp D'!$AP$65 -> 0.0503 | AI11: =0.12*(1-EXP(-50*$AH11))/(1-EXP(-50))+0.24*(1-(1-EXP(-50*$AH11))/(1-EXP(-50))) -> 0.12970355 | AJ11: =(0.11852-0.05478*LN($AH11))^2 -> 0.079692452 | AK11: =(AH$8*NORMSDIST((1-AI11)^(-0.5)*NORMSINV($AH11)+(AI11/(1-AI11))^(0.5)*NORMSINV(0.999))-$AH11*AH$8)*((1+($B11-2.5)*AJ11)/(1-1.5*AJ11)) -> 0.17209803 | AL11: =MAX(AM11-AM10,0.005) -> 0.0547 | AM11: ='[2]Moody''s Global Infra and Corp D'!$AP$66 -> 0.1454 | AN11: =0.12*(1-EXP(-50*$AH11))/(1-EXP(-50))+0.24*(1-(1-EXP(-50*$AH11))/(1-EXP(-50))) -> 0.12970355 | AO11: =(0.11852-0.05478*LN($AM11))^2 -> 0.050243424 | AP11: =(AM$8*NORMSDIST((1-AN11)^(-0.5)*NORMSINV($AM11)+(AN11/(1-AN11))^(0.5)*NORMSINV(0.999))-$AM11*AM$8)*((1+($B11-2.5)*AO11)/(1-1.5*AO11)) -> 0.26036047
B12: 4 | D12: =Q12*100 -> 3.70874 | E12: =V12*100 -> 4.7075801 | F12: =AA12*100 -> 8.2591944 | G12: =AF12*100 -> 12.31143 | H12: =AK12*100 -> 20.966721 | I12: =AP12*100 -> 28.187145 | K12: =H12 -> 20.966721 | N12: ='[2]Moody''s Global Infra and Corp D'!$AQ$61 -> 0.0007 | O12: =0.12*(1-EXP(-50*$N12))/(1-EXP(-50))+0.24*(1-(1-EXP(-50*$N12))/(1-EXP(-50))) -> 0.23587265 | P12: =(0.11852-0.05478*LN($N12))^2 -> 0.2667366 | Q12: =(N$8*NORMSDIST((1-O12)^(-0.5)*NORMSINV($N12)+(O12/(1-O12))^(0.5)*NORMSINV(0.999))-$N12*N$8)*((1+($B12-2.5)*P12)/(1-1.5*P12)) -> 0.0370874 | S12: ='[2]Moody''s Global Infra and Corp D'!$AQ$62 -> 0.0011 | T12: =0.12*(1-EXP(-50*$S12))/(1-EXP(-50))+0.24*(1-(1-EXP(-50*$S12))/(1-EXP(-50))) -> 0.23357822 | U12: =(0.11852-0.05478*LN($S12))^2 -> 0.24177454 | V12: =(S$8*NORMSDIST((1-T12)^(-0.5)*NORMSINV($S12)+(T12/(1-T12))^(0.5)*NORMSINV(0.999))-$S12*S$8)*((1+($B12-2.5)*U12)/(1-1.5*U12)) -> 0.047075801 | X12: ='[2]Moody''s Global Infra and Corp D'!$AQ$63 -> 0.0035 | Y12: =0.12*(1-EXP(-50*$X12))/(1-EXP(-50))+0.24*(1-(1-EXP(-50*$X12))/(1-EXP(-50))) -> 0.22073484 | Z12: =(0.11852-0.05478*LN($X12))^2 -> 0.1834413 | AA12: =(X$8*NORMSDIST((1-Y12)^(-0.5)*NORMSINV($X12)+(Y12/(1-Y12))^(0.5)*NORMSINV(0.999))-$X12*X$8)*((1+($B12-2.5)*Z12)/(1-1.5*Z12)) -> 0.082591944 | AB12: =MAX(AC12-AC11,0) -> 0.0037 | AC12: ='[2]Moody''s Global Infra and Corp D'!$AQ$64 -> 0.0101 | AD12: =0.12*(1-EXP(-50*$AC12))/(1-EXP(-50))+0.24*(1-(1-EXP(-50*$AC12))/(1-EXP(-50))) -> 0.19242067 | AE12: =(0.11852-0.05478*LN($AC12))^2 -> 0.13708221 | AF12: =(AC$8*NORMSDIST((1-AD12)^(-0.5)*NORMSINV($AC12)+(AD12/(1-AD12))^(0.5)*NORMSINV(0.999))-$AC12*AC$8)*((1+($B12-2.5)*AE12)/(1-1.5*AE12)) -> 0.1231143 | AG12: =MAX(AH12-AH11,0) -> 0.0239 | AH12: ='[2]Moody''s Global Infra and Corp D'!$AQ$65 -> 0.0742 | AI12: =0.12*(1-EXP(-50*$AH12))/(1-EXP(-50))+0.24*(1-(1-EXP(-50*$AH12))/(1-EXP(-50))) -> 0.1229373 | AJ12: =(0.11852-0.05478*LN($AH12))^2 -> 0.068122197 | AK12: =(AH$8*NORMSDIST((1-AI12)^(-0.5)*NORMSINV($AH12)+(AI12/(1-AI12))^(0.5)*NORMSINV(0.999))-$AH12*AH$8)*((1+($B12-2.5)*AJ12)/(1-1.5*AJ12)) -> 0.20966721 | AL12: =MAX(AM12-AM11,0.005) -> 0.0488 | AM12: ='[2]Moody''s Global Infra and Corp D'!$AQ$66 -> 0.1942 | AN12: =0.12*(1-EXP(-50*$AH12))/(1-EXP(-50))+0.24*(1-(1-EXP(-50*$AH12))/(1-EXP(-50))) -> 0.1229373 | AO12: =(0.11852-0.05478*LN($AM12))^2 -> 0.04338769 | AP12: =(AM$8*NORMSDIST((1-AN12)^(-0.5)*NORMSINV($AM12)+(AN12/(1-AN12))^(0.5)*NORMSINV(0.999))-$AM12*AM$8)*((1+($B12-2.5)*AO12)/(1-1.5*AO12)) -> 0.28187145
B13: 5 | D13: =Q13*100 -> 6.4488335 | E13: =V13*100 -> 6.8452953 | F13: =AA13*100 -> 10.711519 | G13: =AF13*100 -> 14.954042 | H13: =AK13*100 -> 24.061214 | I13: =AP13*100 -> 29.807527 | K13: =H13 -> 24.061214 | N13: ='[2]Moody''s Global Infra and Corp D'!$AR$61 -> 0.0015 | O13: =0.12*(1-EXP(-50*$N13))/(1-EXP(-50))+0.24*(1-(1-EXP(-50*$N13))/(1-EXP(-50))) -> 0.23132922 | P13: =(0.11852-0.05478*LN($N13))^2 -> 0.22535476 | Q13: =(N$8*NORMSDIST((1-O13)^(-0.5)*NORMSINV($N13)+(O13/(1-O13))^(0.5)*NORMSINV(0.999))-$N13*N$8)*((1+($B13-2.5)*P13)/(1-1.5*P13)) -> 0.064488335 | S13: ='[2]Moody''s Global Infra and Corp D'!$AR$62 -> 0.0017 | T13: =0.12*(1-EXP(-50*$S13))/(1-EXP(-50))+0.24*(1-(1-EXP(-50*$S13))/(1-EXP(-50))) -> 0.23022147 | U13: =(0.11852-0.05478*LN($S13))^2 -> 0.21889206 | V13: =(S$8*NORMSDIST((1-T13)^(-0.5)*NORMSINV($S13)+(T13/(1-T13))^(0.5)*NORMSINV(0.999))-$S13*S$8)*((1+($B13-2.5)*U13)/(1-1.5*U13)) -> 0.068452953 | X13: ='[2]Moody''s Global Infra and Corp D'!$AR$63 -> 0.0048 | Y13: =0.12*(1-EXP(-50*$X13))/(1-EXP(-50))+0.24*(1-(1-EXP(-50*$X13))/(1-EXP(-50))) -> 0.21439534 | Z13: =(0.11852-0.05478*LN($X13))^2 -> 0.1689194 | AA13: =(X$8*NORMSDIST((1-Y13)^(-0.5)*NORMSINV($X13)+(Y13/(1-Y13))^(0.5)*NORMSINV(0.999))-$X13*X$8)*((1+($B13-2.5)*Z13)/(1-1.5*Z13)) -> 0.10711519 | AB13: =MAX(AC13-AC12,0) -> 0.004 | AC13: ='[2]Moody''s Global Infra and Corp D'!$AR$64 -> 0.0141 | AD13: =0.12*(1-EXP(-50*$AC13))/(1-EXP(-50))+0.24*(1-(1-EXP(-50*$AC13))/(1-EXP(-50))) -> 0.17929303 | AE13: =(0.11852-0.05478*LN($AC13))^2 -> 0.12388244 | AF13: =(AC$8*NORMSDIST((1-AD13)^(-0.5)*NORMSINV($AC13)+(AD13/(1-AD13))^(0.5)*NORMSINV(0.999))-$AC13*AC$8)*((1+($B13-2.5)*AE13)/(1-1.5*AE13)) -> 0.14954042 | AG13: =MAX(AH13-AH12,0) -> 0.0206 | AH13: ='[2]Moody''s Global Infra and Corp D'!$AR$65 -> 0.0948 | AI13: =0.12*(1-EXP(-50*$AH13))/(1-EXP(-50))+0.24*(1-(1-EXP(-50*$AH13))/(1-EXP(-50))) -> 0.12104864 | AJ13: =(0.11852-0.05478*LN($AH13))^2 -> 0.061296305 | AK13: =(AH$8*NORMSDIST((1-AI13)^(-0.5)*NORMSINV($AH13)+(AI13/(1-AI13))^(0.5)*NORMSINV(0.999))-$AH13*AH$8)*((1+($B13-2.5)*AJ13)/(1-1.5*AJ13)) -> 0.24061214 | AL13: =MAX(AM13-AM12,0.005) -> 0.0452 | AM13: ='[2]Moody''s Global Infra and Corp D'!$AR$66 -> 0.2394 | AN13: =0.12*(1-EXP(-50*$AH13))/(1-EXP(-50))+0.24*(1-(1-EXP(-50*$AH13))/(1-EXP(-50))) -> 0.12104864 | AO13: =(0.11852-0.05478*LN($AM13))^2 -> 0.038743842 | AP13: =(AM$8*NORMSDIST((1-AN13)^(-0.5)*NORMSINV($AM13)+(AN13/(1-AN13))^(0.5)*NORMSINV(0.999))-$AM13*AM$8)*((1+($B13-2.5)*AO13)/(1-1.5*AO13)) -> 0.29807527
B14: 6 | D14: =Q14*100 -> 9.1013403 | E14: =V14*100 -> 8.5880787 | F14: =AA14*100 -> 13.222733 | G14: =AF14*100 -> 17.234189 | H14: =AK14*100 -> 26.761608 | I14: =AP14*100 -> 30.846321 | K14: =H14 -> 26.761608 | N14: ='[2]Moody''s Global Infra and Corp D'!$AS$61 -> 0.0024 | O14: =0.12*(1-EXP(-50*$N14))/(1-EXP(-50))+0.24*(1-(1-EXP(-50*$N14))/(1-EXP(-50))) -> 0.22643045 | P14: =(0.11852-0.05478*LN($N14))^2 -> 0.20157285 | Q14: =(N$8*NORMSDIST((1-O14)^(-0.5)*NORMSINV($N14)+(O14/(1-O14))^(0.5)*NORMSINV(0.999))-$N14*N$8)*((1+($B14-2.5)*P14)/(1-1.5*P14)) -> 0.091013403 | S14: ='[2]Moody''s Global Infra and Corp D'!$AS$62 -> 0.0021 | T14: =0.12*(1-EXP(-50*$S14))/(1-EXP(-50))+0.24*(1-(1-EXP(-50*$S14))/(1-EXP(-50))) -> 0.22803894 | U14: =(0.11852-0.05478*LN($S14))^2 -> 0.20819464 | V14: =(S$8*NORMSDIST((1-T14)^(-0.5)*NORMSINV($S14)+(T14/(1-T14))^(0.5)*NORMSINV(0.999))-$S14*S$8)*((1+($B14-2.5)*U14)/(1-1.5*U14)) -> 0.085880787 | X14: ='[2]Moody''s Global Infra and Corp D'!$AS$63 -> 0.0064 | Y14: =0.12*(1-EXP(-50*$X14))/(1-EXP(-50))+0.24*(1-(1-EXP(-50*$X14))/(1-EXP(-50))) -> 0.20713788 | Z14: =(0.11852-0.05478*LN($X14))^2 -> 0.15621373 | AA14: =(X$8*NORMSDIST((1-Y14)^(-0.5)*NORMSINV($X14)+(Y14/(1-Y14))^(0.5)*NORMSINV(0.999))-$X14*X$8)*((1+($B14-2.5)*Z14)/(1-1.5*Z14)) -> 0.13222733 | AB14: =MAX(AC14-AC13,0) -> 0.004 | AC14: ='[2]Moody''s Global Infra and Corp D'!$AS$64 -> 0.0181 | AD14: =0.12*(1-EXP(-50*$AC14))/(1-EXP(-50))+0.24*(1-(1-EXP(-50*$AC14))/(1-EXP(-50))) -> 0.16854503 | AE14: =(0.11852-0.05478*LN($AC14))^2 -> 0.1144393 | AF14: =(AC$8*NORMSDIST((1-AD14)^(-0.5)*NORMSINV($AC14)+(AD14/(1-AD14))^(0.5)*NORMSINV(0.999))-$AC14*AC$8)*((1+($B14-2.5)*AE14)/(1-1.5*AE14)) -> 0.17234189 | AG14: =MAX(AH14-AH13,0) -> 0.0198 | AH14: ='[2]Moody''s Global Infra and Corp D'!$AS$65 -> 0.1146 | AI14: =0.12*(1-EXP(-50*$AH14))/(1-EXP(-50))+0.24*(1-(1-EXP(-50*$AH14))/(1-EXP(-50))) -> 0.12038965 | AJ14: =(0.11852-0.05478*LN($AH14))^2 -> 0.05625925 | AK14: =(AH$8*NORMSDIST((1-AI14)^(-0.5)*NORMSINV($AH14)+(AI14/(1-AI14))^(0.5)*NORMSINV(0.999))-$AH14*AH$8)*((1+($B14-2.5)*AJ14)/(1-1.5*AJ14)) -> 0.26761608 | AL14: =MAX(AM14-AM13,0.005) -> 0.0407 | AM14: ='[2]Moody''s Global Infra and Corp D'!$AS$66 -> 0.2801 | AN14: =0.12*(1-EXP(-50*$AH14))/(1-EXP(-50))+0.24*(1-(1-EXP(-50*$AH14))/(1-EXP(-50))) -> 0.12038965 | AO14: =(0.11852-0.05478*LN($AM14))^2 -> 0.03543185 | AP14: =(AM$8*NORMSDIST((1-AN14)^(-0.5)*NORMSINV($AM14)+(AN14/(1-AN14))^(0.5)*NORMSINV(0.999))-$AM14*AM$8)*((1+($B14-2.5)*AO14)/(1-1.5*AO14)) -> 0.30846321
B15: 7 | D15: =Q15*100 -> 11.69384 | E15: =V15*100 -> 10.177024 | F15: =AA15*100 -> 15.591596 | G15: =AF15*100 -> 19.292689 | H15: =AK15*100 -> 29.061929 | I15: =AP15*100 -> 31.454937 | K15: =H15 -> 29.061929 | N15: ='[2]Moody''s Global Infra and Corp D'!$AT$61 -> 0.0034 | O15: =0.12*(1-EXP(-50*$N15))/(1-EXP(-50))+0.24*(1-(1-EXP(-50*$N15))/(1-EXP(-50))) -> 0.22123978 | P15: =(0.11852-0.05478*LN($N15))^2 -> 0.18480405 | Q15: =(N$8*NORMSDIST((1-O15)^(-0.5)*NORMSINV($N15)+(O15/(1-O15))^(0.5)*NORMSINV(0.999))-$N15*N$8)*((1+($B15-2.5)*P15)/(1-1.5*P15)) -> 0.1169384 | S15: ='[2]Moody''s Global Infra and Corp D'!$AT$62 -> 0.0024 | T15: =0.12*(1-EXP(-50*$S15))/(1-EXP(-50))+0.24*(1-(1-EXP(-50*$S15))/(1-EXP(-50))) -> 0.22643045 | U15: =(0.11852-0.05478*LN($S15))^2 -> 0.20157285 | V15: =(S$8*NORMSDIST((1-T15)^(-0.5)*NORMSINV($S15)+(T15/(1-T15))^(0.5)*NORMSINV(0.999))-$S15*S$8)*((1+($B15-2.5)*U15)/(1-1.5*U15)) -> 0.10177024 | X15: ='[2]Moody''s Global Infra and Corp D'!$AT$63 -> 0.0081 | Y15: =0.12*(1-EXP(-50*$X15))/(1-EXP(-50))+0.24*(1-(1-EXP(-50*$X15))/(1-EXP(-50))) -> 0.20003722 | Z15: =(0.11852-0.05478*LN($X15))^2 -> 0.14617969 | AA15: =(X$8*NORMSDIST((1-Y15)^(-0.5)*NORMSINV($X15)+(Y15/(1-Y15))^(0.5)*NORMSINV(0.999))-$X15*X$8)*((1+($B15-2.5)*Z15)/(1-1.5*Z15)) -> 0.15591596 | AB15: =MAX(AC15-AC14,0) -> 0.004 | AC15: ='[2]Moody''s Global Infra and Corp D'!$AT$64 -> 0.0221 | AD15: =0.12*(1-EXP(-50*$AC15))/(1-EXP(-50))+0.24*(1-(1-EXP(-50*$AC15))/(1-EXP(-50))) -> 0.15974531 | AE15: =(0.11852-0.05478*LN($AC15))^2 -> 0.10715874 | AF15: =(AC$8*NORMSDIST((1-AD15)^(-0.5)*NORMSINV($AC15)+(AD15/(1-AD15))^(0.5)*NORMSINV(0.999))-$AC15*AC$8)*((1+($B15-2.5)*AE15)/(1-1.5*AE15)) -> 0.19292689 | AG15: =MAX(AH15-AH14,0) -> 0.0182 | AH15: ='[2]Moody''s Global Infra and Corp D'!$AT$65 -> 0.1328 | AI15: =0.12*(1-EXP(-50*$AH15))/(1-EXP(-50))+0.24*(1-(1-EXP(-50*$AH15))/(1-EXP(-50))) -> 0.12015684 | AJ15: =(0.11852-0.05478*LN($AH15))^2 -> 0.052494117 | AK15: =(AH$8*NORMSDIST((1-AI15)^(-0.5)*NORMSINV($AH15)+(AI15/(1-AI15))^(0.5)*NORMSINV(0.999))-$AH15*AH$8)*((1+($B15-2.5)*AJ15)/(1-1.5*AJ15)) -> 0.29061929 | AL15: =MAX(AM15-AM14,0.005) -> 0.0372 | AM15: ='[2]Moody''s Global Infra and Corp D'!$AT$66 -> 0.3173 | AN15: =0.12*(1-EXP(-50*$AH15))/(1-EXP(-50))+0.24*(1-(1-EXP(-50*$AH15))/(1-EXP(-50))) -> 0.12015684 | AO15: =(0.11852-0.05478*LN($AM15))^2 -> 0.032906822 | AP15: =(AM$8*NORMSDIST((1-AN15)^(-0.5)*NORMSINV($AM15)+(AN15/(1-AN15))^(0.5)*NORMSINV(0.999))-$AM15*AM$8)*((1+($B15-2.5)*AO15)/(1-1.5*AO15)) -> 0.31454937
B16: 8 | D16: =Q16*100 -> 12.873709 | E16: =V16*100 -> 11.791437 | F16: =AA16*100 -> 17.910785 | G16: =AF16*100 -> 21.200313 | H16: =AK16*100 -> 31.067133 | I16: =AP16*100 -> 31.81546 | K16: =H16 -> 31.067133 | N16: ='[2]Moody''s Global Infra and Corp D'!$AU$61 -> 0.0034 | O16: =0.12*(1-EXP(-50*$N16))/(1-EXP(-50))+0.24*(1-(1-EXP(-50*$N16))/(1-EXP(-50))) -> 0.22123978 | P16: =(0.11852-0.05478*LN($N16))^2 -> 0.18480405 | Q16: =(N$8*NORMSDIST((1-O16)^(-0.5)*NORMSINV($N16)+(O16/(1-O16))^(0.5)*NORMSINV(0.999))-$N16*N$8)*((1+($B16-2.5)*P16)/(1-1.5*P16)) -> 0.12873709 | S16: ='[2]Moody''s Global Infra and Corp D'!$AU$62 -> 0.0027 | T16: =0.12*(1-EXP(-50*$S16))/(1-EXP(-50))+0.24*(1-(1-EXP(-50*$S16))/(1-EXP(-50))) -> 0.22484591 | U16: =(0.11852-0.05478*LN($S16))^2 -> 0.19582085 | V16: =(S$8*NORMSDIST((1-T16)^(-0.5)*NORMSINV($S16)+(T16/(1-T16))^(0.5)*NORMSINV(0.999))-$S16*S$8)*((1+($B16-2.5)*U16)/(1-1.5*U16)) -> 0.11791437 | X16: ='[2]Moody''s Global Infra and Corp D'!$AU$63 -> 0.0101 | Y16: =0.12*(1-EXP(-50*$X16))/(1-EXP(-50))+0.24*(1-(1-EXP(-50*$X16))/(1-EXP(-50))) -> 0.19242067 | Z16: =(0.11852-0.05478*LN($X16))^2 -> 0.13708221 | AA16: =(X$8*NORMSDIST((1-Y16)^(-0.5)*NORMSINV($X16)+(Y16/(1-Y16))^(0.5)*NORMSINV(0.999))-$X16*X$8)*((1+($B16-2.5)*Z16)/(1-1.5*Z16)) -> 0.17910785 | AB16: =MAX(AC16-AC15,0) -> 0.0039 | AC16: ='[2]Moody''s Global Infra and Corp D'!$AU$64 -> 0.026 | AD16: =0.12*(1-EXP(-50*$AC16))/(1-EXP(-50))+0.24*(1-(1-EXP(-50*$AC16))/(1-EXP(-50))) -> 0.15270382 | AE16: =(0.11852-0.05478*LN($AC16))^2 -> 0.10140932 | AF16: =(AC$8*NORMSDIST((1-AD16)^(-0.5)*NORMSINV($AC16)+(AD16/(1-AD16))^(0.5)*NORMSINV(0.999))-$AC16*AC$8)*((1+($B16-2.5)*AE16)/(1-1.5*AE16)) -> 0.21200313 | AG16: =MAX(AH16-AH15,0) -> 0.0173 | AH16: ='[2]Moody''s Global Infra and Corp D'!$AU$65 -> 0.1501 | AI16: =0.12*(1-EXP(-50*$AH16))/(1-EXP(-50))+0.24*(1-(1-EXP(-50*$AH16))/(1-EXP(-50))) -> 0.12006604 | AJ16: =(0.11852-0.05478*LN($AH16))^2 -> 0.049465196 | AK16: =(AH$8*NORMSDIST((1-AI16)^(-0.5)*NORMSINV($AH16)+(AI16/(1-AI16))^(0.5)*NORMSINV(0.999))-$AH16*AH$8)*((1+($B16-2.5)*AJ16)/(1-1.5*AJ16)) -> 0.31067133 | AL16: =MAX(AM16-AM15,0.005) -> 0.0307 | AM16: ='[2]Moody''s Global Infra and Corp D'!$AU$66 -> 0.348 | AN16: =0.12*(1-EXP(-50*$AH16))/(1-EXP(-50))+0.24*(1-(1-EXP(-50*$AH16))/(1-EXP(-50))) -> 0.12006604 | AO16: =(0.11852-0.05478*LN($AM16))^2 -> 0.031096918 | AP16: =(AM$8*NORMSDIST((1-AN16)^(-0.5)*NORMSINV($AM16)+(AN16/(1-AN16))^(0.5)*NORMSINV(0.999))-$AM16*AM$8)*((1+($B16-2.5)*AO16)/(1-1.5*AO16)) -> 0.3181546
B17: 9 | D17: =Q17*100 -> 14.053577 | E17: =V17*100 -> 13.748477 | F17: =AA17*100 -> 19.943034 | G17: =AF17*100 -> 23.012607 | H17: =AK17*100 -> 32.836013 | I17: =AP17*100 -> 32.037589 | K17: =H17 -> 32.836013 | N17: ='[2]Moody''s Global Infra and Corp D'!$AV$61 -> 0.0034 | O17: =0.12*(1-EXP(-50*$N17))/(1-EXP(-50))+0.24*(1-(1-EXP(-50*$N17))/(1-EXP(-50))) -> 0.22123978 | P17: =(0.11852-0.05478*LN($N17))^2 -> 0.18480405 | Q17: =(N$8*NORMSDIST((1-O17)^(-0.5)*NORMSINV($N17)+(O17/(1-O17))^(0.5)*NORMSINV(0.999))-$N17*N$8)*((1+($B17-2.5)*P17)/(1-1.5*P17)) -> 0.14053577 | S17: ='[2]Moody''s Global Infra and Corp D'!$AV$62 -> 0.0032 | T17: =0.12*(1-EXP(-50*$S17))/(1-EXP(-50))+0.24*(1-(1-EXP(-50*$S17))/(1-EXP(-50))) -> 0.22225725 | U17: =(0.11852-0.05478*LN($S17))^2 -> 0.18767041 | V17: =(S$8*NORMSDIST((1-T17)^(-0.5)*NORMSINV($S17)+(T17/(1-T17))^(0.5)*NORMSINV(0.999))-$S17*S$8)*((1+($B17-2.5)*U17)/(1-1.5*U17)) -> 0.13748477 | X17: ='[2]Moody''s Global Infra and Corp D'!$AV$63 -> 0.0118 | Y17: =0.12*(1-EXP(-50*$X17))/(1-EXP(-50))+0.24*(1-(1-EXP(-50*$X17))/(1-EXP(-50))) -> 0.18651927 | Z17: =(0.11852-0.05478*LN($X17))^2 -> 0.1308445 | AA17: =(X$8*NORMSDIST((1-Y17)^(-0.5)*NORMSINV($X17)+(Y17/(1-Y17))^(0.5)*NORMSINV(0.999))-$X17*X$8)*((1+($B17-2.5)*Z17)/(1-1.5*Z17)) -> 0.19943034 | AB17: =MAX(AC17-AC16,0) -> 0.0038 | AC17: ='[2]Moody''s Global Infra and Corp D'!$AV$64 -> 0.0298 | AD17: =0.12*(1-EXP(-50*$AC17))/(1-EXP(-50))+0.24*(1-(1-EXP(-50*$AC17))/(1-EXP(-50))) -> 0.14704472 | AE17: =(0.11852-0.05478*LN($AC17))^2 -> 0.096705864 | AF17: =(AC$8*NORMSDIST((1-AD17)^(-0.5)*NORMSINV($AC17)+(AD17/(1-AD17))^(0.5)*NORMSINV(0.999))-$AC17*AC$8)*((1+($B17-2.5)*AE17)/(1-1.5*AE17)) -> 0.23012607 | AG17: =MAX(AH17-AH16,0) -> 0.0168 | AH17: ='[2]Moody''s Global Infra and Corp D'!$AV$65 -> 0.1669 | AI17: =0.12*(1-EXP(-50*$AH17))/(1-EXP(-50))+0.24*(1-(1-EXP(-50*$AH17))/(1-EXP(-50))) -> 0.12002851 | AJ17: =(0.11852-0.05478*LN($AH17))^2 -> 0.046913804 | AK17: =(AH$8*NORMSDIST((1-AI17)^(-0.5)*NORMSINV($AH17)+(AI17/(1-AI17))^(0.5)*NORMSINV(0.999))-$AH17*AH$8)*((1+($B17-2.5)*AJ17)/(1-1.5*AJ17)) -> 0.32836013 | AL17: =MAX(AM17-AM16,0.005) -> 0.0261 | AM17: ='[2]Moody''s Global Infra and Corp D'!$AV$66 -> 0.3741 | AN17: =0.12*(1-EXP(-50*$AH17))/(1-EXP(-50))+0.24*(1-(1-EXP(-50*$AH17))/(1-EXP(-50))) -> 0.12002851 | AO17: =(0.11852-0.05478*LN($AM17))^2 -> 0.029715367 | AP17: =(AM$8*NORMSDIST((1-AN17)^(-0.5)*NORMSINV($AM17)+(AN17/(1-AN17))^(0.5)*NORMSINV(0.999))-$AM17*AM$8)*((1+($B17-2.5)*AO17)/(1-1.5*AO17)) -> 0.32037589
B18: 10 | D18: =Q18*100 -> 15.233446 | E18: =V18*100 -> 15.966283 | F18: =AA18*100 -> 21.756314 | G18: =AF18*100 -> 24.803343 | H18: =AK18*100 -> 34.410529 | I18: =AP18*100 -> 32.218729 | K18: =H18 -> 34.410529 | N18: ='[2]Moody''s Global Infra and Corp D'!$AW$61 -> 0.0034 | O18: =0.12*(1-EXP(-50*$N18))/(1-EXP(-50))+0.24*(1-(1-EXP(-50*$N18))/(1-EXP(-50))) -> 0.22123978 | P18: =(0.11852-0.05478*LN($N18))^2 -> 0.18480405 | Q18: =(N$8*NORMSDIST((1-O18)^(-0.5)*NORMSINV($N18)+(O18/(1-O18))^(0.5)*NORMSINV(0.999))-$N18*N$8)*((1+($B18-2.5)*P18)/(1-1.5*P18)) -> 0.15233446 | S18: ='[2]Moody''s Global Infra and Corp D'!$AW$62 -> 0.0039 | T18: =0.12*(1-EXP(-50*$S18))/(1-EXP(-50))+0.24*(1-(1-EXP(-50*$S18))/(1-EXP(-50))) -> 0.21874016 | U18: =(0.11852-0.05478*LN($S18))^2 -> 0.17839856 | V18: =(S$8*NORMSDIST((1-T18)^(-0.5)*NORMSINV($S18)+(T18/(1-T18))^(0.5)*NORMSINV(0.999))-$S18*S$8)*((1+($B18-2.5)*U18)/(1-1.5*U18)) -> 0.15966283 | X18: ='[2]Moody''s Global Infra and Corp D'!$AW$63 -> 0.0131 | Y18: =0.12*(1-EXP(-50*$X18))/(1-EXP(-50))+0.24*(1-(1-EXP(-50*$X18))/(1-EXP(-50))) -> 0.18233305 | Z18: =(0.11852-0.05478*LN($X18))^2 -> 0.12673538 | AA18: =(X$8*NORMSDIST((1-Y18)^(-0.5)*NORMSINV($X18)+(Y18/(1-Y18))^(0.5)*NORMSINV(0.999))-$X18*X$8)*((1+($B18-2.5)*Z18)/(1-1.5*Z18)) -> 0.21756314 | AB18: =MAX(AC18-AC17,0) -> 0.0041 | AC18: ='[2]Moody''s Global Infra and Corp D'!$AW$64 -> 0.0339 | AD18: =0.12*(1-EXP(-50*$AC18))/(1-EXP(-50))+0.24*(1-(1-EXP(-50*$AC18))/(1-EXP(-50))) -> 0.14203191 | AE18: =(0.11852-0.05478*LN($AC18))^2 -> 0.092363816 | AF18: =(AC$8*NORMSDIST((1-AD18)^(-0.5)*NORMSINV($AC18)+(AD18/(1-AD18))^(0.5)*NORMSINV(0.999))-$AC18*AC$8)*((1+($B18-2.5)*AE18)/(1-1.5*AE18)) -> 0.24803343 | AG18: =MAX(AH18-AH17,0) -> 0.0169 | AH18: ='[2]Moody''s Global Infra and Corp D'!$AW$65 -> 0.1838 | AI18: =0.12*(1-EXP(-50*$AH18))/(1-EXP(-50))+0.24*(1-(1-EXP(-50*$AH18))/(1-EXP(-50))) -> 0.12001225 | AJ18: =(0.11852-0.05478*LN($AH18))^2 -> 0.044652858 | AK18: =(AH$8*NORMSDIST((1-AI18)^(-0.5)*NORMSINV($AH18)+(AI18/(1-AI18))^(0.5)*NORMSINV(0.999))-$AH18*AH$8)*((1+($B18-2.5)*AJ18)/(1-1.5*AJ18)) -> 0.34410529 | AL18: =MAX(AM18-AM17,0.005) -> 0.0213 | AM18: ='[2]Moody''s Global Infra and Corp D'!$AW$66 -> 0.3954 | AN18: =0.12*(1-EXP(-50*$AH18))/(1-EXP(-50))+0.24*(1-(1-EXP(-50*$AH18))/(1-EXP(-50))) -> 0.12001225 | AO18: =(0.11852-0.05478*LN($AM18))^2 -> 0.028678754 | AP18: =(AM$8*NORMSDIST((1-AN18)^(-0.5)*NORMSINV($AM18)+(AN18/(1-AN18))^(0.5)*NORMSINV(0.999))-$AM18*AM$8)*((1+($B18-2.5)*AO18)/(1-1.5*AO18)) -> 0.32218729
D20: Corporate Exposures - Corporate Bank Loans (based on Moody's) - Global | N20: =1-'[2]Moody''s Global Infra and Corp D'!P101 -> 0.196 | S20: =N20 -> 0.196 | X20: =N20 -> 0.196 | AC20: =X20 -> 0.196 | AH20: =X20 -> 0.196 | AM20: =AC20 -> 0.196 | AN20: stdev(rec.) | AO20: 0.305 | AP20: =AO20*(AM20/(1-AM20)) -> 0.074353234
B21: =$B$9 -> 1 | D21: =Q21*100 -> 0.015071274 | E21: =V21*100 -> 0.19190024 | F21: =AA21*100 -> 0.44814729 | G21: =AF21*100 -> 1.0462229 | H21: =AK21*100 -> 2.5080263 | I21: =AP21*100 -> 5.447553 | K21: =H21 -> 2.5080263 | M21: =N21 -> 1e-05 | N21: ='[2]Moody''s Global Infra and Corp D'!AQ89 -> 1e-05 | O21: =0.12*(1-EXP(-50*$N21))/(1-EXP(-50))+0.24*(1-(1-EXP(-50*$N21))/(1-EXP(-50))) -> 0.23994001 | P21: =(0.11852-0.05478*LN($N21))^2 -> 0.56129773 | Q21: =(N$20*NORMSDIST((1-O21)^(-0.5)*NORMSINV($N21)+(O21/(1-O21))^(0.5)*NORMSINV(0.999))-$N21*N$8)*((1+($B21-2.5)*P21)/(1-1.5*P21)) -> 0.00015071274 | R21: =S21 -> 0.0002 | S21: ='[2]Moody''s Global Infra and Corp D'!$AF$91 -> 0.0002 | T21: =0.12*(1-EXP(-50*$S21))/(1-EXP(-50))+0.24*(1-(1-EXP(-50*$S21))/(1-EXP(-50))) -> 0.23880598 | U21: =(0.11852-0.05478*LN($S21))^2 -> 0.34233246 | V21: =(S$20*NORMSDIST((1-T21)^(-0.5)*NORMSINV($S21)+(T21/(1-T21))^(0.5)*NORMSINV(0.999))-$S21*S$20)*((1+($B21-2.5)*U21)/(1-1.5*U21)) -> 0.0019190024 | X21: ='[2]Moody''s Global Infra and Corp D'!$AF$93 -> 0.0006 | Y21: =0.12*(1-EXP(-50*$X21))/(1-EXP(-50))+0.24*(1-(1-EXP(-50*$X21))/(1-EXP(-50))) -> 0.23645346 | Z21: =(0.11852-0.05478*LN($X21))^2 -> 0.27553036 | AA21: =(X$20*NORMSDIST((1-Y21)^(-0.5)*NORMSINV($X21)+(Y21/(1-Y21))^(0.5)*NORMSINV(0.999))-$X21*X$20)*((1+($B21-2.5)*Z21)/(1-1.5*Z21)) -> 0.0044814729 | AB21: =AC21 -> 0.002 | AC21: ='[2]Moody''s Global Infra and Corp D'!$AF$95 -> 0.002 | AD21: =0.12*(1-EXP(-50*$AC21))/(1-EXP(-50))+0.24*(1-(1-EXP(-50*$AC21))/(1-EXP(-50))) -> 0.22858049 | AE21: =(0.11852-0.05478*LN($AC21))^2 -> 0.21064082 | AF21: =(AC$20*NORMSDIST((1-AD21)^(-0.5)*NORMSINV($AC21)+(AD21/(1-AD21))^(0.5)*NORMSINV(0.999))-$AC21*AC$20)*((1+($B21-2.5)*AE21)/(1-1.5*AE21)) -> 0.010462229 | AG21: =AH21 -> 0.0096 | AH21: ='[2]Moody''s Global Infra and Corp D'!$AF$97 -> 0.0096 | AI21: =0.12*(1-EXP(-50*$AH21))/(1-EXP(-50))+0.24*(1-(1-EXP(-50*$AH21))/(1-EXP(-50))) -> 0.19425401 | AJ21: =(0.11852-0.05478*LN($AH21))^2 -> 0.13914948 | AK21: =(AH$20*NORMSDIST((1-AI21)^(-0.5)*NORMSINV($AH21)+(AI21/(1-AI21))^(0.5)*NORMSINV(0.999))-$AH21*AH$20)*((1+($B21-2.5)*AJ21)/(1-1.5*AJ21)) -> 0.025080263 | AL21: =AM21 -> 0.0362 | AM21: ='[2]Moody''s Global Infra and Corp D'!$AF$99 -> 0.0362 | AN21: =0.12*(1-EXP(-50*$AH21))/(1-EXP(-50))+0.24*(1-(1-EXP(-50*$AH21))/(1-EXP(-50))) -> 0.19425401 | AO21: =(0.11852-0.05478*LN($AM21))^2 -> 0.090191007 | AP21: =(AM$20*NORMSDIST((1-AN21)^(-0.5)*NORMSINV($AM21)+(AN21/(1-AN21))^(0.5)*NORMSINV(0.999))-$AM21*AM$20)*((1+($B21-2.5)*AO21)/(1-1.5*AO21)) -> 0.05447553
B22: =$B$10 -> 2 | D22: =Q22*100 -> 0.20333274 | E22: =V22*100 -> 0.72571276 | F22: =AA22*100 -> 1.328646 | G22: =AF22*100 -> 2.2440391 | H22: =AK22*100 -> 4.1115519 | I22: =AP22*100 -> 7.2095748 | K22: =H22 -> 4.1115519 | M22: =N22-N21 -> 9e-05 | N22: ='[2]Moody''s Global Infra and Corp D'!$AG$89 -> 0.0001 | O22: =0.12*(1-EXP(-50*$N22))/(1-EXP(-50))+0.24*(1-(1-EXP(-50*$N22))/(1-EXP(-50))) -> 0.2394015 | P22: =(0.11852-0.05478*LN($N22))^2 -> 0.38820681 | Q22: =(N$20*NORMSDIST((1-O22)^(-0.5)*NORMSINV($N22)+(O22/(1-O22))^(0.5)*NORMSINV(0.999))-$N22*N$8)*((1+($B22-2.5)*P22)/(1-1.5*P22)) -> 0.0020333274 | R22: =S22-S21 -> 0.0005 | S22: ='[2]Moody''s Global Infra and Corp D'!$AG$91 -> 0.0007 | T22: =0.12*(1-EXP(-50*$S22))/(1-EXP(-50))+0.24*(1-(1-EXP(-50*$S22))/(1-EXP(-50))) -> 0.23587265 | U22: =(0.11852-0.05478*LN($S22))^2 -> 0.2667366 | V22: =(S$20*NORMSDIST((1-T22)^(-0.5)*NORMSINV($S22)+(T22/(1-T22))^(0.5)*NORMSINV(0.999))-$S22*S$20)*((1+($B22-2.5)*U22)/(1-1.5*U22)) -> 0.0072571276 | X22: ='[2]Moody''s Global Infra and Corp D'!$AG$93 -> 0.0019 | Y22: =0.12*(1-EXP(-50*$X22))/(1-EXP(-50))+0.24*(1-(1-EXP(-50*$X22))/(1-EXP(-50))) -> 0.22912475 | Z22: =(0.11852-0.05478*LN($X22))^2 -> 0.21322791 | AA22: =(X$20*NORMSDIST((1-Y22)^(-0.5)*NORMSINV($X22)+(Y22/(1-Y22))^(0.5)*NORMSINV(0.999))-$X22*X$20)*((1+($B22-2.5)*Z22)/(1-1.5*Z22)) -> 0.01328646 | AB22: =MAX(AC22-AC21,0) -> 0.0031 | AC22: ='[2]Moody''s Global Infra and Corp D'!$AG$95 -> 0.0051 | AD22: =0.12*(1-EXP(-50*$AC22))/(1-EXP(-50))+0.24*(1-(1-EXP(-50*$AC22))/(1-EXP(-50))) -> 0.21298998 | AE22: =(0.11852-0.05478*LN($AC22))^2 -> 0.16620057 | AF22: =(AC$20*NORMSDIST((1-AD22)^(-0.5)*NORMSINV($AC22)+(AD22/(1-AD22))^(0.5)*NORMSINV(0.999))-$AC22*AC$20)*((1+($B22-2.5)*AE22)/(1-1.5*AE22)) -> 0.022440391 | AG22: =MAX(AH22-AH21,0) -> 0.017 | AH22: ='[2]Moody''s Global Infra and Corp D'!$AG$97 -> 0.0266 | AI22: =0.12*(1-EXP(-50*$AH22))/(1-EXP(-50))+0.24*(1-(1-EXP(-50*$AH22))/(1-EXP(-50))) -> 0.15173727 | AJ22: =(0.11852-0.05478*LN($AH22))^2 -> 0.1006149 | AK22: =(AH$20*NORMSDIST((1-AI22)^(-0.5)*NORMSINV($AH22)+(AI22/(1-AI22))^(0.5)*NORMSINV(0.999))-$AH22*AH$20)*((1+($B22-2.5)*AJ22)/(1-1.5*AJ22)) -> 0.041115519 | AL22: =MAX(AM22-AM21,0) -> 0.0494 | AM22: ='[2]Moody''s Global Infra and Corp D'!$AG$99 -> 0.0856 | AN22: =0.12*(1-EXP(-50*$AH22))/(1-EXP(-50))+0.24*(1-(1-EXP(-50*$AH22))/(1-EXP(-50))) -> 0.15173727 | AO22: =(0.11852-0.05478*LN($AM22))^2 -> 0.064096606 | AP22: =(AM$20*NORMSDIST((1-AN22)^(-0.5)*NORMSINV($AM22)+(AN22/(1-AN22))^(0.5)*NORMSINV(0.999))-$AM22*AM$20)*((1+($B22-2.5)*AO22)/(1-1.5*AO22)) -> 0.072095748
B23: =$B$11 -> 3 | D23: =Q23*100 -> 0.30127974 | E23: =V23*100 -> 1.2845289 | F23: =AA23*100 -> 2.3514354 | G23: =AF23*100 -> 3.2472315 | H23: =AK23*100 -> 5.3360452 | I23: =AP23*100 -> 8.1332935 | K23: =H23 -> 5.3360452 | M23: =N23-N22 -> 0 | N23: ='[2]Moody''s Global Infra and Corp D'!$AH$89 -> 0.0001 | O23: =0.12*(1-EXP(-50*$N23))/(1-EXP(-50))+0.24*(1-(1-EXP(-50*$N23))/(1-EXP(-50))) -> 0.2394015 | P23: =(0.11852-0.05478*LN($N23))^2 -> 0.38820681 | Q23: =(N$20*NORMSDIST((1-O23)^(-0.5)*NORMSINV($N23)+(O23/(1-O23))^(0.5)*NORMSINV(0.999))-$N23*N$8)*((1+($B23-2.5)*P23)/(1-1.5*P23)) -> 0.0030127974 | R23: =S23-S22 -> 0.0005 | S23: ='[2]Moody''s Global Infra and Corp D'!$AH$91 -> 0.0012 | T23: =0.12*(1-EXP(-50*$S23))/(1-EXP(-50))+0.24*(1-(1-EXP(-50*$S23))/(1-EXP(-50))) -> 0.23301174 | U23: =(0.11852-0.05478*LN($S23))^2 -> 0.23710984 | V23: =(S$20*NORMSDIST((1-T23)^(-0.5)*NORMSINV($S23)+(T23/(1-T23))^(0.5)*NORMSINV(0.999))-$S23*S$20)*((1+($B23-2.5)*U23)/(1-1.5*U23)) -> 0.012845289 | X23: ='[2]Moody''s Global Infra and Corp D'!$AH$93 -> 0.0039 | Y23: =0.12*(1-EXP(-50*$X23))/(1-EXP(-50))+0.24*(1-(1-EXP(-50*$X23))/(1-EXP(-50))) -> 0.21874016 | Z23: =(0.11852-0.05478*LN($X23))^2 -> 0.17839856 | AA23: =(X$20*NORMSDIST((1-Y23)^(-0.5)*NORMSINV($X23)+(Y23/(1-Y23))^(0.5)*NORMSINV(0.999))-$X23*X$20)*((1+($B23-2.5)*Z23)/(1-1.5*Z23)) -> 0.023514354 | AB23: =MAX(AC23-AC22,0) -> 0.0034 | AC23: ='[2]Moody''s Global Infra and Corp D'!$AH$95 -> 0.0085 | AD23: =0.12*(1-EXP(-50*$AC23))/(1-EXP(-50))+0.24*(1-(1-EXP(-50*$AC23))/(1-EXP(-50))) -> 0.19845237 | AE23: =(0.11852-0.05478*LN($AC23))^2 -> 0.14416754 | AF23: =(AC$20*NORMSDIST((1-AD23)^(-0.5)*NORMSINV($AC23)+(AD23/(1-AD23))^(0.5)*NORMSINV(0.999))-$AC23*AC$20)*((1+($B23-2.5)*AE23)/(1-1.5*AE23)) -> 0.032472315 | AG23: =MAX(AH23-AH22,0) -> 0.0207 | AH23: ='[2]Moody''s Global Infra and Corp D'!$AH$97 -> 0.0473 | AI23: =0.12*(1-EXP(-50*$AH23))/(1-EXP(-50))+0.24*(1-(1-EXP(-50*$AH23))/(1-EXP(-50))) -> 0.13127392 | AJ23: =(0.11852-0.05478*LN($AH23))^2 -> 0.081605749 | AK23: =(AH$20*NORMSDIST((1-AI23)^(-0.5)*NORMSINV($AH23)+(AI23/(1-AI23))^(0.5)*NORMSINV(0.999))-$AH23*AH$20)*((1+($B23-2.5)*AJ23)/(1-1.5*AJ23)) -> 0.053360452 | AL23: =MAX(AM23-AM22,0) -> 0.0503 | AM23: ='[2]Moody''s Global Infra and Corp D'!$AH$99 -> 0.1359 | AN23: =0.12*(1-EXP(-50*$AH23))/(1-EXP(-50))+0.24*(1-(1-EXP(-50*$AH23))/(1-EXP(-50))) -> 0.13127392 | AO23: =(0.11852-0.05478*LN($AM23))^2 -> 0.051916485 | AP23: =(AM$20*NORMSDIST((1-AN23)^(-0.5)*NORMSINV($AM23)+(AN23/(1-AN23))^(0.5)*NORMSINV(0.999))-$AM23*AM$20)*((1+($B23-2.5)*AO23)/(1-1.5*AO23)) -> 0.081332935
B24: =$B$12 -> 4 | D24: =Q24*100 -> 0.82284292 | E24: =V24*100 -> 2.0609903 | F24: =AA24*100 -> 3.2766987 | G24: =AF24*100 -> 4.1608492 | H24: =AK24*100 -> 6.469057 | I24: =AP24*100 -> 8.8280096 | K24: =H24 -> 6.469057 | M24: =N24-N23 -> 0.0003 | N24: ='[2]Moody''s Global Infra and Corp D'!$AI$89 -> 0.0004 | O24: =0.12*(1-EXP(-50*$N24))/(1-EXP(-50))+0.24*(1-(1-EXP(-50*$N24))/(1-EXP(-50))) -> 0.23762384 | P24: =(0.11852-0.05478*LN($N24))^2 -> 0.29934165 | Q24: =(N$20*NORMSDIST((1-O24)^(-0.5)*NORMSINV($N24)+(O24/(1-O24))^(0.5)*NORMSINV(0.999))-$N24*N$8)*((1+($B24-2.5)*P24)/(1-1.5*P24)) -> 0.0082284292 | R24: =S24-S23 -> 0.0009 | S24: ='[2]Moody''s Global Infra and Corp D'!$AI$91 -> 0.0021 | T24: =0.12*(1-EXP(-50*$S24))/(1-EXP(-50))+0.24*(1-(1-EXP(-50*$S24))/(1-EXP(-50))) -> 0.22803894 | U24: =(0.11852-0.05478*LN($S24))^2 -> 0.20819464 | V24: =(S$20*NORMSDIST((1-T24)^(-0.5)*NORMSINV($S24)+(T24/(1-T24))^(0.5)*NORMSINV(0.999))-$S24*S$20)*((1+($B24-2.5)*U24)/(1-1.5*U24)) -> 0.020609903 | X24: ='[2]Moody''s Global Infra and Corp D'!$AI$93 -> 0.0061 | Y24: =0.12*(1-EXP(-50*$X24))/(1-EXP(-50))+0.24*(1-(1-EXP(-50*$X24))/(1-EXP(-50))) -> 0.2084548 | Z24: =(0.11852-0.05478*LN($X24))^2 -> 0.15829956 | AA24: =(X$20*NORMSDIST((1-Y24)^(-0.5)*NORMSINV($X24)+(Y24/(1-Y24))^(0.5)*NORMSINV(0.999))-$X24*X$20)*((1+($B24-2.5)*Z24)/(1-1.5*Z24)) -> 0.032766987 | AB24: =MAX(AC24-AC23,0) -> 0.0042 | AC24: ='[2]Moody''s Global Infra and Corp D'!$AI$95 -> 0.0127 | AD24: =0.12*(1-EXP(-50*$AC24))/(1-EXP(-50))+0.24*(1-(1-EXP(-50*$AC24))/(1-EXP(-50))) -> 0.18359226 | AE24: =(0.11852-0.05478*LN($AC24))^2 -> 0.12794777 | AF24: =(AC$20*NORMSDIST((1-AD24)^(-0.5)*NORMSINV($AC24)+(AD24/(1-AD24))^(0.5)*NORMSINV(0.999))-$AC24*AC$20)*((1+($B24-2.5)*AE24)/(1-1.5*AE24)) -> 0.041608492 | AG24: =MAX(AH24-AH23,0) -> 0.0217 | AH24: ='[2]Moody''s Global Infra and Corp D'!$AI$97 -> 0.069 | AI24: =0.12*(1-EXP(-50*$AH24))/(1-EXP(-50))+0.24*(1-(1-EXP(-50*$AH24))/(1-EXP(-50))) -> 0.12380948 | AJ24: =(0.11852-0.05478*LN($AH24))^2 -> 0.070215715 | AK24: =(AH$20*NORMSDIST((1-AI24)^(-0.5)*NORMSINV($AH24)+(AI24/(1-AI24))^(0.5)*NORMSINV(0.999))-$AH24*AH$20)*((1+($B24-2.5)*AJ24)/(1-1.5*AJ24)) -> 0.06469057 | AL24: =MAX(AM24-AM23,0) -> 0.045 | AM24: ='[2]Moody''s Global Infra and Corp D'!$AI$99 -> 0.1809 | AN24: =0.12*(1-EXP(-50*$AH24))/(1-EXP(-50))+0.24*(1-(1-EXP(-50*$AH24))/(1-EXP(-50))) -> 0.12380948 | AO24: =(0.11852-0.05478*LN($AM24))^2 -> 0.045021812 | AP24: =(AM$20*NORMSDIST((1-AN24)^(-0.5)*NORMSINV($AM24)+(AN24/(1-AN24))^(0.5)*NORMSINV(0.999))-$AM24*AM$20)*((1+($B24-2.5)*AO24)/(1-1.5*AO24)) -> 0.088280096
B25: =$B$13 -> 5 | D25: =Q25*100 -> 1.3133367 | E25: =V25*100 -> 2.8765219 | F25: =AA25*100 -> 4.1497793 | G25: =AF25*100 -> 4.9221279 | H25: =AK25*100 -> 7.4319462 | I25: =AP25*100 -> 9.3757764 | K25: =H25 -> 7.4319462 | M25: =N25-N24 -> 0.0003 | N25: ='[2]Moody''s Global Infra and Corp D'!$AJ$89 -> 0.0007 | O25: =0.12*(1-EXP(-50*$N25))/(1-EXP(-50))+0.24*(1-(1-EXP(-50*$N25))/(1-EXP(-50))) -> 0.23587265 | P25: =(0.11852-0.05478*LN($N25))^2 -> 0.2667366 | Q25: =(N$20*NORMSDIST((1-O25)^(-0.5)*NORMSINV($N25)+(O25/(1-O25))^(0.5)*NORMSINV(0.999))-$N25*N$8)*((1+($B25-2.5)*P25)/(1-1.5*P25)) -> 0.013133367 | R25: =S25-S24 -> 0.0011 | S25: ='[2]Moody''s Global Infra and Corp D'!$AJ$91 -> 0.0032 | T25: =0.12*(1-EXP(-50*$S25))/(1-EXP(-50))+0.24*(1-(1-EXP(-50*$S25))/(1-EXP(-50))) -> 0.22225725 | U25: =(0.11852-0.05478*LN($S25))^2 -> 0.18767041 | V25: =(S$20*NORMSDIST((1-T25)^(-0.5)*NORMSINV($S25)+(T25/(1-T25))^(0.5)*NORMSINV(0.999))-$S25*S$20)*((1+($B25-2.5)*U25)/(1-1.5*U25)) -> 0.028765219 | X25: ='[2]Moody''s Global Infra and Corp D'!$AJ$93 -> 0.0087 | Y25: =0.12*(1-EXP(-50*$X25))/(1-EXP(-50))+0.24*(1-(1-EXP(-50*$X25))/(1-EXP(-50))) -> 0.19767176 | Z25: =(0.11852-0.05478*LN($X25))^2 -> 0.1432017 | AA25: =(X$20*NORMSDIST((1-Y25)^(-0.5)*NORMSINV($X25)+(Y25/(1-Y25))^(0.5)*NORMSINV(0.999))-$X25*X$20)*((1+($B25-2.5)*Z25)/(1-1.5*Z25)) -> 0.041497793 | AB25: =MAX(AC25-AC24,0) -> 0.0041 | AC25: ='[2]Moody''s Global Infra and Corp D'!$AJ$95 -> 0.0168 | AD25: =0.12*(1-EXP(-50*$AC25))/(1-EXP(-50))+0.24*(1-(1-EXP(-50*$AC25))/(1-EXP(-50))) -> 0.17180526 | AE25: =(0.11852-0.05478*LN($AC25))^2 -> 0.11721838 | AF25: =(AC$20*NORMSDIST((1-AD25)^(-0.5)*NORMSINV($AC25)+(AD25/(1-AD25))^(0.5)*NORMSINV(0.999))-$AC25*AC$20)*((1+($B25-2.5)*AE25)/(1-1.5*AE25)) -> 0.049221279 | AG25: =MAX(AH25-AH24,0) -> 0.0191 | AH25: ='[2]Moody''s Global Infra and Corp D'!$AJ$97 -> 0.0881 | AI25: =0.12*(1-EXP(-50*$AH25))/(1-EXP(-50))+0.24*(1-(1-EXP(-50*$AH25))/(1-EXP(-50))) -> 0.12146593 | AJ25: =(0.11852-0.05478*LN($AH25))^2 -> 0.063300602 | AK25: =(AH$20*NORMSDIST((1-AI25)^(-0.5)*NORMSINV($AH25)+(AI25/(1-AI25))^(0.5)*NORMSINV(0.999))-$AH25*AH$20)*((1+($B25-2.5)*AJ25)/(1-1.5*AJ25)) -> 0.074319462 | AL25: =MAX(AM25-AM24,0) -> 0.0409 | AM25: ='[2]Moody''s Global Infra and Corp D'!$AJ$99 -> 0.2218 | AN25: =0.12*(1-EXP(-50*$AH25))/(1-EXP(-50))+0.24*(1-(1-EXP(-50*$AH25))/(1-EXP(-50))) -> 0.12146593 | AO25: =(0.11852-0.05478*LN($AM25))^2 -> 0.040408052 | AP25: =(AM$20*NORMSDIST((1-AN25)^(-0.5)*NORMSINV($AM25)+(AN25/(1-AN25))^(0.5)*NORMSINV(0.999))-$AM25*AM$20)*((1+($B25-2.5)*AO25)/(1-1.5*AO25)) -> 0.093757764
B26: =$B$14 -> 6 | D26: =Q26*100 -> 1.800765 | E26: =V26*100 -> 3.6068728 | F26: =AA26*100 -> 4.9467305 | G26: =AF26*100 -> 5.6046796 | H26: =AK26*100 -> 8.2692404 | I26: =AP26*100 -> 9.7645973 | K26: =H26 -> 8.2692404 | M26: =N26-N25 -> 0.0003 | N26: ='[2]Moody''s Global Infra and Corp D'!$AK$89 -> 0.001 | O26: =0.12*(1-EXP(-50*$N26))/(1-EXP(-50))+0.24*(1-(1-EXP(-50*$N26))/(1-EXP(-50))) -> 0.23414753 | P26: =(0.11852-0.05478*LN($N26))^2 -> 0.24693628 | Q26: =(N$20*NORMSDIST((1-O26)^(-0.5)*NORMSINV($N26)+(O26/(1-O26))^(0.5)*NORMSINV(0.999))-$N26*N$8)*((1+($B26-2.5)*P26)/(1-1.5*P26)) -> 0.01800765 | R26: =S26-S25 -> 0.001 | S26: ='[2]Moody''s Global Infra and Corp D'!$AK$91 -> 0.0042 | T26: =0.12*(1-EXP(-50*$S26))/(1-EXP(-50))+0.24*(1-(1-EXP(-50*$S26))/(1-EXP(-50))) -> 0.21727011 | U26: =(0.11852-0.05478*LN($S26))^2 -> 0.17498569 | V26: =(S$20*NORMSDIST((1-T26)^(-0.5)*NORMSINV($S26)+(T26/(1-T26))^(0.5)*NORMSINV(0.999))-$S26*S$20)*((1+($B26-2.5)*U26)/(1-1.5*U26)) -> 0.036068728 | X26: ='[2]Moody''s Global Infra and Corp D'!$AK$93 -> 0.0116 | Y26: =0.12*(1-EXP(-50*$X26))/(1-EXP(-50))+0.24*(1-(1-EXP(-50*$X26))/(1-EXP(-50))) -> 0.1871878 | Z26: =(0.11852-0.05478*LN($X26))^2 -> 0.13152284 | AA26: =(X$20*NORMSDIST((1-Y26)^(-0.5)*NORMSINV($X26)+(Y26/(1-Y26))^(0.5)*NORMSINV(0.999))-$X26*X$20)*((1+($B26-2.5)*Z26)/(1-1.5*Z26)) -> 0.049467305 | AB26: =MAX(AC26-AC25,0) -> 0.0042 | AC26: ='[2]Moody''s Global Infra and Corp D'!$AK$95 -> 0.021 | AD26: =0.12*(1-EXP(-50*$AC26))/(1-EXP(-50))+0.24*(1-(1-EXP(-50*$AC26))/(1-EXP(-50))) -> 0.16199253 | AE26: =(0.11852-0.05478*LN($AC26))^2 -> 0.10899763 | AF26: =(AC$20*NORMSDIST((1-AD26)^(-0.5)*NORMSINV($AC26)+(AD26/(1-AD26))^(0.5)*NORMSINV(0.999))-$AC26*AC$20)*((1+($B26-2.5)*AE26)/(1-1.5*AE26)) -> 0.056046796 | AG26: =MAX(AH26-AH25,0) -> 0.0176 | AH26: ='[2]Moody''s Global Infra and Corp D'!$AK$97 -> 0.1057 | AI26: =0.12*(1-EXP(-50*$AH26))/(1-EXP(-50))+0.24*(1-(1-EXP(-50*$AH26))/(1-EXP(-50))) -> 0.12060804 | AJ26: =(0.11852-0.05478*LN($AH26))^2 -> 0.058379692 | AK26: =(AH$20*NORMSDIST((1-AI26)^(-0.5)*NORMSINV($AH26)+(AI26/(1-AI26))^(0.5)*NORMSINV(0.999))-$AH26*AH$20)*((1+($B26-2.5)*AJ26)/(1-1.5*AJ26)) -> 0.082692404 | AL26: =MAX(AM26-AM25,0) -> 0.0368 | AM26: ='[2]Moody''s Global Infra and Corp D'!$AK$99 -> 0.2586 | AN26: =0.12*(1-EXP(-50*$AH26))/(1-EXP(-50))+0.24*(1-(1-EXP(-50*$AH26))/(1-EXP(-50))) -> 0.12060804 | AO26: =(0.11852-0.05478*LN($AM26))^2 -> 0.037098019 | AP26: =(AM$20*NORMSDIST((1-AN26)^(-0.5)*NORMSINV($AM26)+(AN26/(1-AN26))^(0.5)*NORMSINV(0.999))-$AM26*AM$20)*((1+($B26-2.5)*AO26)/(1-1.5*AO26)) -> 0.097645973
B27: =$B$15 -> 7 | D27: =Q27*100 -> 2.3626814 | E27: =V27*100 -> 4.3057852 | F27: =AA27*100 -> 5.6610021 | G27: =AF27*100 -> 6.2251289 | H27: =AK27*100 -> 8.9873118 | I27: =AP27*100 -> 10.030088 | K27: =H27 -> 8.9873118 | M27: =N27-N26 -> 0.0004 | N27: ='[2]Moody''s Global Infra and Corp D'!$AL$89 -> 0.0014 | O27: =0.12*(1-EXP(-50*$N27))/(1-EXP(-50))+0.24*(1-(1-EXP(-50*$N27))/(1-EXP(-50))) -> 0.23188726 | P27: =(0.11852-0.05478*LN($N27))^2 -> 0.22895736 | Q27: =(N$20*NORMSDIST((1-O27)^(-0.5)*NORMSINV($N27)+(O27/(1-O27))^(0.5)*NORMSINV(0.999))-$N27*N$8)*((1+($B27-2.5)*P27)/(1-1.5*P27)) -> 0.023626814 | R27: =S27-S26 -> 0.001 | S27: ='[2]Moody''s Global Infra and Corp D'!$AL$91 -> 0.0052 | T27: =0.12*(1-EXP(-50*$S27))/(1-EXP(-50))+0.24*(1-(1-EXP(-50*$S27))/(1-EXP(-50))) -> 0.21252619 | U27: =(0.11852-0.05478*LN($S27))^2 -> 0.16533439 | V27: =(S$20*NORMSDIST((1-T27)^(-0.5)*NORMSINV($S27)+(T27/(1-T27))^(0.5)*NORMSINV(0.999))-$S27*S$20)*((1+($B27-2.5)*U27)/(1-1.5*U27)) -> 0.043057852 | X27: ='[2]Moody''s Global Infra and Corp D'!$AL$93 -> 0.0146 | Y27: =0.12*(1-EXP(-50*$X27))/(1-EXP(-50))+0.24*(1-(1-EXP(-50*$X27))/(1-EXP(-50))) -> 0.17782908 | Z27: =(0.11852-0.05478*LN($X27))^2 -> 0.12254234 | AA27: =(X$20*NORMSDIST((1-Y27)^(-0.5)*NORMSINV($X27)+(Y27/(1-Y27))^(0.5)*NORMSINV(0.999))-$X27*X$20)*((1+($B27-2.5)*Z27)/(1-1.5*Z27)) -> 0.056610021 | AB27: =MAX(AC27-AC26,0) -> 0.004 | AC27: ='[2]Moody''s Global Infra and Corp D'!$AL$95 -> 0.025 | AD27: =0.12*(1-EXP(-50*$AC27))/(1-EXP(-50))+0.24*(1-(1-EXP(-50*$AC27))/(1-EXP(-50))) -> 0.15438058 | AE27: =(0.11852-0.05478*LN($AC27))^2 -> 0.10278232 | AF27: =(AC$20*NORMSDIST((1-AD27)^(-0.5)*NORMSINV($AC27)+(AD27/(1-AD27))^(0.5)*NORMSINV(0.999))-$AC27*AC$20)*((1+($B27-2.5)*AE27)/(1-1.5*AE27)) -> 0.062251289 | AG27: =MAX(AH27-AH26,0) -> 0.0156 | AH27: ='[2]Moody''s Global Infra and Corp D'!$AL$97 -> 0.1213 | AI27: =0.12*(1-EXP(-50*$AH27))/(1-EXP(-50))+0.24*(1-(1-EXP(-50*$AH27))/(1-EXP(-50))) -> 0.12027873 | AJ27: =(0.11852-0.05478*LN($AH27))^2 -> 0.054792406 | AK27: =(AH$20*NORMSDIST((1-AI27)^(-0.5)*NORMSINV($AH27)+(AI27/(1-AI27))^(0.5)*NORMSINV(0.999))-$AH27*AH$20)*((1+($B27-2.5)*AJ27)/(1-1.5*AJ27)) -> 0.089873118 | AL27: =MAX(AM27-AM26,0) -> 0.0335 | AM27: ='[2]Moody''s Global Infra and Corp D'!$AL$99 -> 0.2921 | AN27: =0.12*(1-EXP(-50*$AH27))/(1-EXP(-50))+0.24*(1-(1-EXP(-50*$AH27))/(1-EXP(-50))) -> 0.12027873 | AO27: =(0.11852-0.05478*LN($AM27))^2 -> 0.034572012 | AP27: =(AM$20*NORMSDIST((1-AN27)^(-0.5)*NORMSINV($AM27)+(AN27/(1-AN27))^(0.5)*NORMSINV(0.999))-$AM27*AM$20)*((1+($B27-2.5)*AO27)/(1-1.5*AO27)) -> 0.10030088
B28: =$B$16 -> 8 | D28: =Q28*100 -> 2.6291204 | E28: =V28*100 -> 4.9287927 | F28: =AA28*100 -> 6.3154495 | G28: =AF28*100 -> 6.8142206 | H28: =AK28*100 -> 9.6268699 | I28: =AP28*100 -> 10.214806 | K28: =H28 -> 9.6268699 | M28: =N28-N27 -> 0 | N28: ='[2]Moody''s Global Infra and Corp D'!$AM$89 -> 0.0014 | O28: =0.12*(1-EXP(-50*$N28))/(1-EXP(-50))+0.24*(1-(1-EXP(-50*$N28))/(1-EXP(-50))) -> 0.23188726 | P28: =(0.11852-0.05478*LN($N28))^2 -> 0.22895736 | Q28: =(N$20*NORMSDIST((1-O28)^(-0.5)*NORMSINV($N28)+(O28/(1-O28))^(0.5)*NORMSINV(0.999))-$N28*N$8)*((1+($B28-2.5)*P28)/(1-1.5*P28)) -> 0.026291204 | R28: =S28-S27 -> 0.0008 | S28: ='[2]Moody''s Global Infra and Corp D'!$AM$91 -> 0.006 | T28: =0.12*(1-EXP(-50*$S28))/(1-EXP(-50))+0.24*(1-(1-EXP(-50*$S28))/(1-EXP(-50))) -> 0.20889819 | U28: =(0.11852-0.05478*LN($S28))^2 -> 0.1590209 | V28: =(S$20*NORMSDIST((1-T28)^(-0.5)*NORMSINV($S28)+(T28/(1-T28))^(0.5)*NORMSINV(0.999))-$S28*S$20)*((1+($B28-2.5)*U28)/(1-1.5*U28)) -> 0.049287927 | X28: ='[2]Moody''s Global Infra and Corp D'!$AM$93 -> 0.0177 | Y28: =0.12*(1-EXP(-50*$X28))/(1-EXP(-50))+0.24*(1-(1-EXP(-50*$X28))/(1-EXP(-50))) -> 0.1695257 | Z28: =(0.11852-0.05478*LN($X28))^2 -> 0.11526905 | AA28: =(X$20*NORMSDIST((1-Y28)^(-0.5)*NORMSINV($X28)+(Y28/(1-Y28))^(0.5)*NORMSINV(0.999))-$X28*X$20)*((1+($B28-2.5)*Z28)/(1-1.5*Z28)) -> 0.063154495 | AB28: =MAX(AC28-AC27,0) -> 0.004 | AC28: ='[2]Moody''s Global Infra and Corp D'!$AM$95 -> 0.029 | AD28: =0.12*(1-EXP(-50*$AC28))/(1-EXP(-50))+0.24*(1-(1-EXP(-50*$AC28))/(1-EXP(-50))) -> 0.14814843 | AE28: =(0.11852-0.05478*LN($AC28))^2 -> 0.097635232 | AF28: =(AC$20*NORMSDIST((1-AD28)^(-0.5)*NORMSINV($AC28)+(AD28/(1-AD28))^(0.5)*NORMSINV(0.999))-$AC28*AC$20)*((1+($B28-2.5)*AE28)/(1-1.5*AE28)) -> 0.068142206 | AG28: =MAX(AH28-AH27,0) -> 0.0147 | AH28: ='[2]Moody''s Global Infra and Corp D'!$AM$97 -> 0.136 | AI28: =0.12*(1-EXP(-50*$AH28))/(1-EXP(-50))+0.24*(1-(1-EXP(-50*$AH28))/(1-EXP(-50))) -> 0.12013365 | AJ28: =(0.11852-0.05478*LN($AH28))^2 -> 0.051898125 | AK28: =(AH$20*NORMSDIST((1-AI28)^(-0.5)*NORMSINV($AH28)+(AI28/(1-AI28))^(0.5)*NORMSINV(0.999))-$AH28*AH$20)*((1+($B28-2.5)*AJ28)/(1-1.5*AJ28)) -> 0.096268699 | AL28: =MAX(AM28-AM27,0) -> 0.028 | AM28: ='[2]Moody''s Global Infra and Corp D'!$AM$99 -> 0.3201 | AN28: =0.12*(1-EXP(-50*$AH28))/(1-EXP(-50))+0.24*(1-(1-EXP(-50*$AH28))/(1-EXP(-50))) -> 0.12013365 | AO28: =(0.11852-0.05478*LN($AM28))^2 -> 0.032732442 | AP28: =(AM$20*NORMSDIST((1-AN28)^(-0.5)*NORMSINV($AM28)+(AN28/(1-AN28))^(0.5)*NORMSINV(0.999))-$AM28*AM$20)*((1+($B28-2.5)*AO28)/(1-1.5*AO28)) -> 0.10214806
B29: =$B$17 -> 9 | D29: =Q29*100 -> 2.8955595 | E29: =V29*100 -> 5.5165878 | F29: =AA29*100 -> 6.9312821 | G29: =AF29*100 -> 7.3900124 | H29: =AK29*100 -> 10.20193 | I29: =AP29*100 -> 10.350553 | K29: =H29 -> 10.20193 | M29: =N29-N28 -> 0 | N29: ='[2]Moody''s Global Infra and Corp D'!$AN$89 -> 0.0014 | O29: =0.12*(1-EXP(-50*$N29))/(1-EXP(-50))+0.24*(1-(1-EXP(-50*$N29))/(1-EXP(-50))) -> 0.23188726 | P29: =(0.11852-0.05478*LN($N29))^2 -> 0.22895736 | Q29: =(N$20*NORMSDIST((1-O29)^(-0.5)*NORMSINV($N29)+(O29/(1-O29))^(0.5)*NORMSINV(0.999))-$N29*N$8)*((1+($B29-2.5)*P29)/(1-1.5*P29)) -> 0.028955595 | R29: =S29-S28 -> 0.0007 | S29: ='[2]Moody''s Global Infra and Corp D'!$AN$91 -> 0.0067 | T29: =0.12*(1-EXP(-50*$S29))/(1-EXP(-50))+0.24*(1-(1-EXP(-50*$S29))/(1-EXP(-50))) -> 0.20584057 | U29: =(0.11852-0.05478*LN($S29))^2 -> 0.15423637 | V29: =(S$20*NORMSDIST((1-T29)^(-0.5)*NORMSINV($S29)+(T29/(1-T29))^(0.5)*NORMSINV(0.999))-$S29*S$20)*((1+($B29-2.5)*U29)/(1-1.5*U29)) -> 0.055165878 | X29: ='[2]Moody''s Global Infra and Corp D'!$AN$93 -> 0.021 | Y29: =0.12*(1-EXP(-50*$X29))/(1-EXP(-50))+0.24*(1-(1-EXP(-50*$X29))/(1-EXP(-50))) -> 0.16199253 | Z29: =(0.11852-0.05478*LN($X29))^2 -> 0.10899763 | AA29: =(X$20*NORMSDIST((1-Y29)^(-0.5)*NORMSINV($X29)+(Y29/(1-Y29))^(0.5)*NORMSINV(0.999))-$X29*X$20)*((1+($B29-2.5)*Z29)/(1-1.5*Z29)) -> 0.069312821 | AB29: =MAX(AC29-AC28,0) -> 0.0042 | AC29: ='[2]Moody''s Global Infra and Corp D'!$AN$95 -> 0.0332 | AD29: =0.12*(1-EXP(-50*$AC29))/(1-EXP(-50))+0.24*(1-(1-EXP(-50*$AC29))/(1-EXP(-50))) -> 0.14281668 | AE29: =(0.11852-0.05478*LN($AC29))^2 -> 0.093059866 | AF29: =(AC$20*NORMSDIST((1-AD29)^(-0.5)*NORMSINV($AC29)+(AD29/(1-AD29))^(0.5)*NORMSINV(0.999))-$AC29*AC$20)*((1+($B29-2.5)*AE29)/(1-1.5*AE29)) -> 0.073900124 | AG29: =MAX(AH29-AH28,0) -> 0.014 | AH29: ='[2]Moody''s Global Infra and Corp D'!$AN$97 -> 0.15 | AI29: =0.12*(1-EXP(-50*$AH29))/(1-EXP(-50))+0.24*(1-(1-EXP(-50*$AH29))/(1-EXP(-50))) -> 0.12006637 | AJ29: =(0.11852-0.05478*LN($AH29))^2 -> 0.049481437 | AK29: =(AH$20*NORMSDIST((1-AI29)^(-0.5)*NORMSINV($AH29)+(AI29/(1-AI29))^(0.5)*NORMSINV(0.999))-$AH29*AH$20)*((1+($B29-2.5)*AJ29)/(1-1.5*AJ29)) -> 0.1020193 | AL29: =MAX(AM29-AM28,0) -> 0.0241 | AM29: ='[2]Moody''s Global Infra and Corp D'!$AN$99 -> 0.3442 | AN29: =0.12*(1-EXP(-50*$AH29))/(1-EXP(-50))+0.24*(1-(1-EXP(-50*$AH29))/(1-EXP(-50))) -> 0.12006637 | AO29: =(0.11852-0.05478*LN($AM29))^2 -> 0.031309407 | AP29: =(AM$20*NORMSDIST((1-AN29)^(-0.5)*NORMSINV($AM29)+(AN29/(1-AN29))^(0.5)*NORMSINV(0.999))-$AM29*AM$20)*((1+($B29-2.5)*AO29)/(1-1.5*AO29)) -> 0.10350553
B30: =$B$18 -> 10 | D30: =Q30*100 -> 3.1619985 | E30: =V30*100 -> 6.1369224 | F30: =AA30*100 -> 7.5031323 | G30: =AF30*100 -> 7.9651789 | H30: =AK30*100 -> 10.728777 | I30: =AP30*100 -> 10.472943 | K30: =H30 -> 10.728777 | M30: =N30-N29 -> 0 | N30: ='[2]Moody''s Global Infra and Corp D'!$AO$89 -> 0.0014 | O30: =0.12*(1-EXP(-50*$N30))/(1-EXP(-50))+0.24*(1-(1-EXP(-50*$N30))/(1-EXP(-50))) -> 0.23188726 | P30: =(0.11852-0.05478*LN($N30))^2 -> 0.22895736 | Q30: =(N$20*NORMSDIST((1-O30)^(-0.5)*NORMSINV($N30)+(O30/(1-O30))^(0.5)*NORMSINV(0.999))-$N30*N$8)*((1+($B30-2.5)*P30)/(1-1.5*P30)) -> 0.031619985 | R30: =S30-S29 -> 0.0009 | S30: ='[2]Moody''s Global Infra and Corp D'!$AO$91 -> 0.0076 | T30: =0.12*(1-EXP(-50*$S30))/(1-EXP(-50))+0.24*(1-(1-EXP(-50*$S30))/(1-EXP(-50))) -> 0.20206337 | U30: =(0.11852-0.05478*LN($S30))^2 -> 0.14886083 | V30: =(S$20*NORMSDIST((1-T30)^(-0.5)*NORMSINV($S30)+(T30/(1-T30))^(0.5)*NORMSINV(0.999))-$S30*S$20)*((1+($B30-2.5)*U30)/(1-1.5*U30)) -> 0.061369224 | X30: ='[2]Moody''s Global Infra and Corp D'!$AO$93 -> 0.0241 | Y30: =0.12*(1-EXP(-50*$X30))/(1-EXP(-50))+0.24*(1-(1-EXP(-50*$X30))/(1-EXP(-50))) -> 0.15596304 | Z30: =(0.11852-0.05478*LN($X30))^2 -> 0.10407416 | AA30: =(X$20*NORMSDIST((1-Y30)^(-0.5)*NORMSINV($X30)+(Y30/(1-Y30))^(0.5)*NORMSINV(0.999))-$X30*X$20)*((1+($B30-2.5)*Z30)/(1-1.5*Z30)) -> 0.075031323 | AB30: =MAX(AC30-AC29,0) -> 0.0046 | AC30: ='[2]Moody''s Global Infra and Corp D'!$AO$95 -> 0.0378 | AD30: =0.12*(1-EXP(-50*$AC30))/(1-EXP(-50))+0.24*(1-(1-EXP(-50*$AC30))/(1-EXP(-50))) -> 0.13812862 | AE30: =(0.11852-0.05478*LN($AC30))^2 -> 0.088773572 | AF30: =(AC$20*NORMSDIST((1-AD30)^(-0.5)*NORMSINV($AC30)+(AD30/(1-AD30))^(0.5)*NORMSINV(0.999))-$AC30*AC$20)*((1+($B30-2.5)*AE30)/(1-1.5*AE30)) -> 0.079651789 | AG30: =MAX(AH30-AH29,0) -> 0.0141 | AH30: ='[2]Moody''s Global Infra and Corp D'!$AO$97 -> 0.1641 | AI30: =0.12*(1-EXP(-50*$AH30))/(1-EXP(-50))+0.24*(1-(1-EXP(-50*$AH30))/(1-EXP(-50))) -> 0.12003279 | AJ30: =(0.11852-0.05478*LN($AH30))^2 -> 0.047316151 | AK30: =(AH$20*NORMSDIST((1-AI30)^(-0.5)*NORMSINV($AH30)+(AI30/(1-AI30))^(0.5)*NORMSINV(0.999))-$AH30*AH$20)*((1+($B30-2.5)*AJ30)/(1-1.5*AJ30)) -> 0.10728777 | AL30: =MAX(AM30-AM29,0) -> 0.0189 | AM30: ='[2]Moody''s Global Infra and Corp D'!$AO$99 -> 0.3631 | AN30: =0.12*(1-EXP(-50*$AH30))/(1-EXP(-50))+0.24*(1-(1-EXP(-50*$AH30))/(1-EXP(-50))) -> 0.12003279 | AO30: =(0.11852-0.05478*LN($AM30))^2 -> 0.030281693 | AP30: =(AM$20*NORMSDIST((1-AN30)^(-0.5)*NORMSINV($AM30)+(AN30/(1-AN30))^(0.5)*NORMSINV(0.999))-$AM30*AM$20)*((1+($B30-2.5)*AO30)/(1-1.5*AO30)) -> 0.10472943 | AY30: PPP only | BE30: F-IRB (LGD=45%) | BK30: PPP only
D32: ='[2]Table - SII - Interim'!D27:R27 -> Infrastructure Investment (Global) 3/ | N32: =1-'[2]Moody''s Global Infra and Corp D'!P98 -> 0.44 | S32: =N32 -> 0.44 | X32: =N32 -> 0.44 | AC32: =X32 -> 0.44 | AH32: =X32 -> 0.44 | AM32: =AC32 -> 0.44 | AN32: stdev(rec.) | AO32: =AO8*AM32/AM8 -> 0.23916129 | AP32: =AO32*(AM32/(1-AM32)) -> 0.18791244 | AS32: Marginal PD ↓/Recovery → | AT32: =1-'[2]default rates (3)'!CR13/100 -> 0.20519401 | AU32: stdev(rec.) | AV32: ='[2]default rates (3)'!CS13 -> 0.3371022 | AW32: =AV32*(AT32/(1-AT32)) -> 0.087029228 | AY32: Marginal PD ↓/Recovery → | AZ32: =1-'[3]default rates'!$CR$66/100 -> 0.14192385 | BA32: stdev(rec.) | BB32: ='[3]default rates'!$CS$66 -> 0.29046617 | BC32: =BB32*(AZ32/(1-AZ32)) -> 0.048042445 | BE32: Marginal PD ↓/Recovery → | BF32: 0.45 | BG32: stdev(rec.) | BH32: =BF32/AT32*AV32 -> 0.73928079 | BI32: =BH32*(BF32/(1-BF32)) -> 0.6048661 | BK32: Marginal PD ↓/Recovery → | BL32: =BF32 -> 0.45 | BM32: stdev(rec.) | BN32: ='[3]default rates'!$CS$66 -> 0.29046617 | BO32: =BN32*(BL32/(1-BL32)) -> 0.23765414
