Workbook
Name _Ref171698474: MM_GEMsRt_Up!$A$2

Sheet DR
C2: Table 1: Overall average default rate
C4: Counter- parties | D4: Observed years | E4: Number of defaults | F4: Number of observations | G4: Signed amount € million | H4: Lower of 90% confidence interval | I4: Average default rate | J4: Upper of 90% confidence interval
C5: 10476 | D5: 31 | E5: 2101 | F5: 59361 | G5: 446360.85 | H5: 0.031889333 | I5: 0.035393609 | J5: 0.038897884

Sheet DR_Year
Q2: Table 4: Annual default rates
B3: Figure 1: Annual default rates
Q4: Year | R4: Signed amount € million | S4: Number of defaults | T4: Active counterparties | U4: Default rate | W4: Overall average | X4: ="Average "&$Q6&"-"&$Q15 -> Average 1995-2004 | Y4: ="Average "&$Q16&"-"&$Q25 -> Average 2005-2014 | Z4: ="Average "&$Q26&"-"&$Q35 -> Average 2015-2024
Q5: 1994 | R5: 7922.2769 | S5: 13 | T5: 530 | U5: 0.024528302 | W5: =U37 -> 0.035393609
Q6: 1995 | R6: 10863.275 | S6: 20 | T6: 613 | U6: 0.032626427 | V6: =((S6-S5)/(T6-T5))*U5 -> 0.002068652 | W6: =W5 -> 0.035393609 | X6: =SUM($S6:$S15)/SUM($T6:$T15) -> 0.051426559
Q7: 1996 | R7: 14745.529 | S7: 13 | T7: 700 | U7: 0.018571429 | V7: =((S7-S6)/(T7-T6))*U6 -> -0.0026251148 | W7: =W6 -> 0.035393609 | X7: =X6 -> 0.051426559
Q8: 1997 | R8: 17273.045 | S8: 29 | T8: 754 | U8: 0.038461538 | V8: =((S8-S7)/(T8-T7))*U7 -> 0.0055026455 | W8: =W7 -> 0.035393609 | X8: =X7 -> 0.051426559
Q9: 1998 | R9: 19274.241 | S9: 67 | T9: 769 | U9: 0.087126138 | V9: =((S9-S8)/(T9-T8))*U8 -> 0.097435897 | W9: =W8 -> 0.035393609 | X9: =X8 -> 0.051426559
Q10: 1999 | R10: 21607.418 | S10: 34 | T10: 815 | U10: 0.041717791 | V10: =((S10-S9)/(T10-T9))*U9 -> -0.062503534 | W10: =W9 -> 0.035393609 | X10: =X9 -> 0.051426559
Q11: 2000 | R11: 27399.963 | S11: 38 | T11: 896 | U11: 0.042410714 | V11: =((S11-S10)/(T11-T10))*U10 -> 0.0020601378 | W11: =W10 -> 0.035393609 | X11: =X10 -> 0.051426559
Q12: 2001 | R12: 29836.363 | S12: 49 | T12: 942 | U12: 0.052016985 | V12: =((S12-S11)/(T12-T11))*U11 -> 0.010141693 | W12: =W11 -> 0.035393609 | X12: =X11 -> 0.051426559
Q13: 2002 | R13: 35431.857 | S13: 76 | T13: 980 | U13: 0.07755102 | V13: =((S13-S12)/(T13-T12))*U12 -> 0.036959437 | W13: =W12 -> 0.035393609 | X13: =X12 -> 0.051426559
Q14: 2003 | R14: 39134.171 | S14: 68 | T14: 995 | U14: 0.068341709 | V14: =((S14-S13)/(T14-T13))*U13 -> -0.041360544 | W14: =W13 -> 0.035393609 | X14: =X13 -> 0.051426559
Q15: 2004 | R15: 47796.308 | S15: 44 | T15: 1053 | U15: 0.041785375 | V15: =((S15-S14)/(T15-T14))*U14 -> -0.028279328 | W15: =W14 -> 0.035393609 | X15: =X14 -> 0.051426559
Q16: 2005 | R16: 53217.757 | S16: 35 | T16: 1155 | U16: 0.03030303 | V16: =((S16-S15)/(T16-T15))*U15 -> -0.0036869449 | W16: =W15 -> 0.035393609 | Y16: =SUM($S16:$S25)/SUM($T16:$T25) -> 0.032565302
Q17: 2006 | R17: 60067.189 | S17: 38 | T17: 1245 | U17: 0.030522088 | V17: =((S17-S16)/(T17-T16))*U16 -> 0.001010101 | W17: =W16 -> 0.035393609 | Y17: =Y16 -> 0.032565302
Q18: 2007 | R18: 65421.939 | S18: 37 | T18: 1303 | U18: 0.028396009 | V18: =((S18-S17)/(T18-T17))*U17 -> -0.0005262429 | W18: =W17 -> 0.035393609 | Y18: =Y17 -> 0.032565302
Q19: 2008 | R19: 74981.766 | S19: 49 | T19: 1484 | U19: 0.033018868 | V19: =((S19-S18)/(T19-T18))*U18 -> 0.0018826083 | W19: =W18 -> 0.035393609 | Y19: =Y18 -> 0.032565302
Q20: 2009 | R20: 85584.745 | S20: 62 | T20: 1697 | U20: 0.036535062 | V20: =((S20-S19)/(T20-T19))*U19 -> 0.0020152361 | W20: =W19 -> 0.035393609 | Y20: =Y19 -> 0.032565302
Q21: 2010 | R21: 94477.822 | S21: 74 | T21: 1819 | U21: 0.040681693 | V21: =((S21-S20)/(T21-T20))*U20 -> 0.0035936126 | W21: =W20 -> 0.035393609 | Y21: =Y20 -> 0.032565302
Q22: 2011 | R22: 103204.81 | S22: 60 | T22: 1948 | U22: 0.030800821 | V22: =((S22-S21)/(T22-T21))*U21 -> -0.0044150675 | W22: =W21 -> 0.035393609 | Y22: =Y21 -> 0.032565302
Q23: 2012 | R23: 114336.61 | S23: 66 | T23: 2115 | U23: 0.031205674 | V23: =((S23-S22)/(T23-T22))*U22 -> 0.0011066163 | W23: =W22 -> 0.035393609 | Y23: =Y22 -> 0.032565302
Q24: 2013 | R24: 131087.47 | S24: 53 | T24: 2328 | U24: 0.022766323 | V24: =((S24-S23)/(T24-T23))*U23 -> -0.0019045716 | W24: =W23 -> 0.035393609 | Y24: =Y23 -> 0.032565302
Q25: 2014 | R25: 137957.74 | S25: 97 | T25: 2440 | U25: 0.039754098 | V25: =((S25-S24)/(T25-T24))*U24 -> 0.0089439126 | W25: =W24 -> 0.035393609 | Y25: =Y24 -> 0.032565302
Q26: 2015 | R26: 171555.24 | S26: 90 | T26: 3071 | U26: 0.029306415 | V26: =((S26-S25)/(T26-T25))*U25 -> -0.00044101218 | W26: =W25 -> 0.035393609 | Z26: =SUM($S26:$S35)/SUM($T26:$T35) -> 0.032916412
Q27: 2016 | R27: 180298.46 | S27: 115 | T27: 3143 | U27: 0.036589246 | V27: =((S27-S26)/(T27-T26))*U26 -> 0.010175838 | W27: =W26 -> 0.035393609 | Z27: =Z26 -> 0.032916412
Q28: 2017 | R28: 196268.51 | S28: 98 | T28: 3155 | U28: 0.031061807 | V28: =((S28-S27)/(T28-T27))*U27 -> -0.051834765 | W28: =W27 -> 0.035393609 | Z28: =Z27 -> 0.032916412
Q29: 2018 | R29: 206027.22 | S29: 89 | T29: 3209 | U29: 0.027734497 | V29: =((S29-S28)/(T29-T28))*U28 -> -0.0051769678 | W29: =W28 -> 0.035393609 | Z29: =Z28 -> 0.032916412
Q30: 2019 | R30: 216576.04 | S30: 116 | T30: 3327 | U30: 0.034866246 | V30: =((S30-S29)/(T30-T29))*U29 -> 0.0063460289 | W30: =W29 -> 0.035393609 | Z30: =Z29 -> 0.032916412
Q31: 2020 | R31: 224028.91 | S31: 173 | T31: 3396 | U31: 0.050942285 | V31: =((S31-S30)/(T31-T30))*U30 -> 0.028802551 | W31: =W30 -> 0.035393609 | Z31: =Z30 -> 0.032916412
Q32: 2021 | R32: 222992.58 | S32: 102 | T32: 3343 | U32: 0.030511517 | V32: =((S32-S31)/(T32-T31))*U31 -> 0.068243438 | W32: =W31 -> 0.035393609 | Z32: =Z31 -> 0.032916412
Q33: 2022 | R33: 224376.36 | S33: 108 | T33: 3354 | U33: 0.032200358 | V33: =((S33-S32)/(T33-T32))*U32 -> 0.016642645 | W33: =W32 -> 0.035393609 | Z33: =Z32 -> 0.032916412
Q34: 2023 | R34: 229318.94 | S34: 110 | T34: 3360 | U34: 0.032738095 | V34: =((S34-S33)/(T34-T33))*U33 -> 0.010733453 | W34: =W33 -> 0.035393609 | Z34: =Z33 -> 0.032916412
Q35: 2024 | R35: 240900.03 | S35: 78 | T35: 3422 | U35: 0.022793688 | V35: =((S35-S34)/(T35-T34))*U34 -> -0.016897081 | W35: =W34 -> 0.035393609 | Z35: =Z34 -> 0.032916412
Q36: 2023 | R36: 229318.94 | S36: 110 | T36: 3360 | U36: 0.032738095 | V36: =((S36-S35)/(T36-T35))*U35 -> -0.011764484 | W36: =W35 -> 0.035393609 | Z36: =Z35 -> 0.032916412
Q37: Overall | S37: =DR!E5 -> 2101 | T37: =DR!F5 -> 59361 | U37: =DR!I5 -> 0.035393609 | V37: =SUMPRODUCT(V6:V35,T6:T35)/SUM(T6:T35) -> 0.0043523222
V38: =AVERAGE(V7:V35) -> 0.0031705061

Sheet DR_TtD
B2: Figure 2: Time to default
F29: 0 | G29: 1 | H29: 2 | I29: 3 | J29: 4 | K29: 5 | L29: 6 | M29: 7 | N29: 8 | O29: 9 | P29: 10 | Q29: 11 | R29: 12 | S29: 13 | T29: 14 | U29: 15 | V29: 16 | W29: 17 | X29: 18 | Y29: 19 | Z29: >=20
D30: 2401 | E30: All | F30: 0.067471887 | G30: 0.22199084 | H30: 0.42149105 | I30: 0.59600167 | J30: 0.70970429 | K30: 0.79008746 | L30: 0.85714286 | M30: 0.89421075 | N30: 0.93252811 | O30: 0.95251978 | P30: 0.96626406 | Q30: 0.97459392 | R30: 0.98375677 | S30: 0.99000416 | T30: 0.9937526 | U30: 0.99583507 | V30: 0.99833403 | W30: 0.99875052 | X30: 0.99875052 | Y30: 0.99875052 | Z30: 1

Sheet DR_Rat_1y
B2: Figure 3: One-year default rates by credit rating
B29: Gi1 | C29: Gi2 | D29: Gi3 | E29: Gi4 | F29: Gi5 | G29: Gi6 | H29: Gi7 | I29: Gi8 | J29: Gi9 | K29: Gi10 | L29: Gs1 | M29: Gs2 | N29: Gs3 | O29: Gs4 | P29: Gs5 | Q29: Gs6 | R29: Gs7 | S29: Gs8 | T29: Gs9 | U29: Gs10
A30: Default rate by credit rating | B30: 0 | C30: 0 | D30: 0 | E30: 0 | F30: 0 | G30: 0 | H30: 0 | I30: 0.001 | J30: 0.0025 | K30: 0.0043 | L30: 0.0075 | M30: 0.0128 | N30: 0.0199 | O30: 0.0269 | P30: 0.0336 | Q30: 0.0481 | R30: 0.0714 | S30: 0.1059 | T30: 0.1645 | U30: 0.2462
A31: Average default rate | B31: =+DR!I5 -> 0.035393609 | C31: =$B$31 -> 0.035393609 | D31: =$B$31 -> 0.035393609 | E31: =$B$31 -> 0.035393609 | F31: =$B$31 -> 0.035393609 | G31: =$B$31 -> 0.035393609 | H31: =$B$31 -> 0.035393609 | I31: =$B$31 -> 0.035393609 | J31: =$B$31 -> 0.035393609 | ... U31: =$B$31 -> 0.035393609

Sheet RR
C2: Table 2: Overall average recovery rate
C4: Number of defaults | D4: Signed amount € million | E4: Average recovery rate | F4: Minimum observation | G4: 10th percentile | H4: 25th percentile | I4: Median | J4: 75th percentile | K4: 90th percentile | L4: Maximum observation
C5: 1801 | D5: 27449.833 | E5: 0.72934569 | F5: 0 | G5: 0.11136894 | H5: 0.50618334 | I5: 0.91081311 | J5: 0.99822109 | K5: 1 | L5: 1

Sheet RR_year
Z1: =SUM(Z4:Z440) -> 1801 | AA1: =SUMPRODUCT(AA4:AA40,Z4:Z40)/Z1 -> 0.72934569
A2: Figure 4: Annual recovery rates | Q2: Table 32: Recovery rates by year of default | Y2: years | Z2: Default count (right y-axis) | AA2: Recovery rate (left y-axis) | AB2: Average
Y4: 1994 | Z4: 18 | AA4: 0.72362125 | AB4: 0.72934569
Q5: Year | R5: Defaults | S5: Recovery rate | U5: Year | V5: Defaults | W5: Recovery rate | Y5: 1995 | Z5: 16 | AA5: 0.52030336 | AB5: =+AB4 -> 0.72934569
Q6: =+Y4 -> 1994 | R6: =+Z4 -> 18 | S6: =IF(R6=0,"",AA4) -> 0.72362125 | U6: =1+Q21 -> 2010 | V6: =+Z20 -> 83 | W6: =IF(V6=0,"",AA20) -> 0.77642992 | Y6: 1996 | Z6: 16 | AA6: 0.59583538 | AB6: =+AB5 -> 0.72934569
Q7: =+Y5 -> 1995 | R7: =+Z5 -> 16 | S7: =IF(R7=0,"",AA5) -> 0.52030336 | U7: =1+U6 -> 2011 | V7: =+Z21 -> 73 | W7: =IF(V7=0,"",AA21) -> 0.78730317 | Y7: 1997 | Z7: 27 | AA7: 0.59472568 | AB7: =+AB6 -> 0.72934569
Q8: =+Y6 -> 1996 | R8: =+Z6 -> 16 | S8: =IF(R8=0,"",AA6) -> 0.59583538 | U8: =1+U7 -> 2012 | V8: =+Z22 -> 58 | W8: =IF(V8=0,"",AA22) -> 0.73583452 | Y8: 1998 | Z8: 77 | AA8: 0.77279503 | AB8: =+AB7 -> 0.72934569
Q9: =+Y7 -> 1997 | R9: =+Z7 -> 27 | S9: =IF(R9=0,"",AA7) -> 0.59472568 | U9: =1+U8 -> 2013 | V9: =+Z23 -> 54 | W9: =IF(V9=0,"",AA23) -> 0.64062508 | Y9: 1999 | Z9: 35 | AA9: 0.73508957 | AB9: =+AB8 -> 0.72934569
Q10: =+Y8 -> 1998 | R10: =+Z8 -> 77 | S10: =IF(R10=0,"",AA8) -> 0.77279503 | U10: =1+U9 -> 2014 | V10: =+Z24 -> 85 | W10: =IF(V10=0,"",AA24) -> 0.64392746 | Y10: 2000 | Z10: 39 | AA10: 0.61683444 | AB10: =+AB9 -> 0.72934569
Q11: =+Y9 -> 1999 | R11: =+Z9 -> 35 | S11: =IF(R11=0,"",AA9) -> 0.73508957 | U11: =1+U10 -> 2015 | V11: =+Z25 -> 97 | W11: =IF(V11=0,"",AA25) -> 0.70944317 | Y11: 2001 | Z11: 49 | AA11: 0.65194748 | AB11: =+AB10 -> 0.72934569
Q12: =+Y10 -> 2000 | R12: =+Z10 -> 39 | S12: =IF(R12=0,"",AA10) -> 0.61683444 | U12: =1+U11 -> 2016 | V12: =+Z26 -> 129 | W12: =IF(V12=0,"",AA26) -> 0.6070832 | Y12: 2002 | Z12: 63 | AA12: 0.72695865 | AB12: =+AB11 -> 0.72934569
Q13: =+Y11 -> 2001 | R13: =+Z11 -> 49 | S13: =IF(R13=0,"",AA11) -> 0.65194748 | U13: =1+U12 -> 2017 | V13: =+Z27 -> 75 | W13: =IF(V13=0,"",AA27) -> 0.77818471 | Y13: 2003 | Z13: 70 | AA13: 0.86917204 | AB13: =+AB12 -> 0.72934569
Q14: =+Y12 -> 2002 | R14: =+Z12 -> 63 | S14: =IF(R14=0,"",AA12) -> 0.72695865 | U14: =1+U13 -> 2018 | V14: =+Z28 -> 66 | W14: =IF(V14=0,"",AA28) -> 0.61791099 | Y14: 2004 | Z14: 39 | AA14: 0.76820651 | AB14: =+AB13 -> 0.72934569
Q15: =+Y13 -> 2003 | R15: =+Z13 -> 70 | S15: =IF(R15=0,"",AA13) -> 0.86917204 | U15: =1+U14 -> 2019 | V15: =+Z29 -> 84 | W15: =IF(V15=0,"",AA29) -> 0.70717151 | Y15: 2005 | Z15: 36 | AA15: 0.71203126 | AB15: =+AB14 -> 0.72934569
Q16: =+Y14 -> 2004 | R16: =+Z14 -> 39 | S16: =IF(R16=0,"",AA14) -> 0.76820651 | U16: =1+U15 -> 2020 | V16: =+Z30 -> 119 | W16: =IF(V16=0,"",AA30) -> 0.80116281 | Y16: 2006 | Z16: 36 | AA16: 0.72490495 | AB16: =+AB15 -> 0.72934569
Q17: =+Y15 -> 2005 | R17: =+Z15 -> 36 | S17: =IF(R17=0,"",AA15) -> 0.71203126 | U17: =1+U16 -> 2021 | V17: =+Z31 -> 64 | W17: =IF(V17=0,"",AA31) -> 0.79352137 | Y17: 2007 | Z17: 32 | AA17: 0.80005508 | AB17: =+AB16 -> 0.72934569
Q18: =+Y16 -> 2006 | R18: =+Z16 -> 36 | S18: =IF(R18=0,"",AA16) -> 0.72490495 | U18: =1+U17 -> 2022 | V18: =+Z32 -> 57 | W18: =IF(V18=0,"",AA32) -> 0.86025224 | Y18: 2008 | Z18: 60 | AA18: 0.79896292 | AB18: =+AB17 -> 0.72934569
... Q20: =+Y18 -> 2008 | R20: =+Z18 -> 60 | S20: =IF(R20=0,"",AA18) -> 0.79896292 | U20: =1+U19 -> 2024 | V20: =+Z34 -> 30 | W20: =IF(V20=0,"",AA34) -> 0.79757452 | Y20: 2010 | Z20: 83 | AA20: 0.77642992 | AB20: =+AB19 -> 0.72934569
Q21: =+Y19 -> 2009 | R21: =+Z19 -> 69 | S21: =IF(R21=0,"",AA19) -> 0.71629177 | U21: Total | V21: =+$Z$1 -> 1801 | W21: 0.72934569 | Y21: 2011 | Z21: 73 | AA21: 0.78730317 | AB21: =+AB20 -> 0.72934569
Y22: 2012 | Z22: 58 | AA22: 0.73583452 | AB22: =+AB21 -> 0.72934569
R23: =SUM(R6:R22) -> 682 | V23: =SUM(V6:V20) -> 1119 | Y23: 2013 | Z23: 54 | AA23: 0.64062508 | AB23: =+AB22 -> 0.72934569
V24: =R23+V23 -> 1801 | Y24: 2014 | Z24: 85 | AA24: 0.64392746 | AB24: =+AB23 -> 0.72934569
Y25: 2015 | Z25: 97 | AA25: 0.70944317 | AB25: =+AB24 -> 0.72934569
Y26: 2016 | Z26: 129 | AA26: 0.6070832 | AB26: =+AB25 -> 0.72934569
A27: Table 17: Recovery rates by year of default | Y27: 2017 | Z27: 75 | AA27: 0.77818471 | AB27: =+AB26 -> 0.72934569
Y28: 2018 | Z28: 66 | AA28: 0.61791099 | AB28: =+AB27 -> 0.72934569
Y29: 2019 | Z29: 84 | AA29: 0.70717151 | AB29: =+AB28 -> 0.72934569
Y30: 2020 | Z30: 119 | AA30: 0.80116281 | AB30: =+AB29 -> 0.72934569
Y31: 2021 | Z31: 64 | AA31: 0.79352137 | AB31: =+AB30 -> 0.72934569
Y32: 2022 | Z32: 57 | AA32: 0.86025224 | AB32: =+AB31 -> 0.72934569
Y33: 2023 | Z33: 45 | AA33: 0.78655865 | AB33: =+AB32 -> 0.72934569
Y34: 2024 | Z34: 30 | AA34: 0.79757452 | AB34: =+AB33 -> 0.72934569

Sheet RR_Dist
B2: Figure 5: Distribution of recovery rates
C29: Table 33: Distribution of recovery rates
D31: Recovery rate | E31: From | F31: 0 | G31: =F32 -> 0.1 | H31: =G32 -> 0.2 | I31: =H32 -> 0.3 | J31: =I32 -> 0.4 | K31: =J32 -> 0.5 | L31: =K32 -> 0.6 | M31: =L32 -> 0.7 | N31: =M32 -> 0.8 | O31: =N32 -> 0.9 | P31: Total
E32: To | F32: 0.1 | G32: =G31+$F$32 -> 0.2 | H32: =H31+$F$32 -> 0.3 | I32: =I31+$F$32 -> 0.4 | J32: =J31+$F$32 -> 0.5 | K32: =K31+$F$32 -> 0.6 | L32: =L31+$F$32 -> 0.7 | M32: =M31+$F$32 -> 0.8 | N32: =N31+$F$32 -> 0.9 | O32: =O31+$F$32 -> 1
D33: Defaulted contracts | F33: =+G37 -> 173 | G33: =+H37 -> 64 | H33: =+I37 -> 78 | I33: =+J37 -> 60 | J33: =+K37 -> 70 | K33: =+L37 -> 74 | L33: =+M37 -> 82 | M33: =+N37 -> 103 | ... O33: =+P37 -> 931 | P33: =SUM(F33:O33) -> 1801
D34: % of total | F34: =F33/$P$33 -> 0.096057746 | G34: =G33/$P$33 -> 0.035535813 | H34: =H33/$P$33 -> 0.043309273 | I34: =I33/$P$33 -> 0.033314825 | J34: =J33/$P$33 -> 0.038867296 | K34: =K33/$P$33 -> 0.041088284 | L34: =L33/$P$33 -> 0.045530261 | M34: =M33/$P$33 -> 0.05719045 | ... P34: =P33/$P$33 -> 1
D36: Submission_Year | E36: cod_category_ctp | F36: CountOfid_contract | G36: 0_1 | H36: 0_2 | I36: 0_3 | J36: 0_4 | K36: 0_5 | L36: 0_6 | M36: 0_7 | N36: 0_8 | O36: 0_9 | P36: 1
D37: 2024 | E37: Private | F37: 1801 | G37: 173 | H37: 64 | I37: 78 | J37: 60 | K37: 70 | L37: 74 | M37: 82 | N37: 103 | O37: 166 | P37: 931
H39: ="below "&TEXT(F32,"0%") -> below 10% | I39: 10-20% | J39: 20-30% | K39: 30-40% | L39: 40-50% | M39: 50-60% | N39: 60-70% | O39: 70-80% | P39: 80-90% | Q39: 90-100%

Sheet RR_TtR
B2: Figure 6: Time to resolution
Q29: Table 34: Time to resolution
S31: Resolution of default during year | AM31: Total
S32: 1 | T32: =1+S32 -> 2 | U32: =1+T32 -> 3 | V32: =1+U32 -> 4 | W32: =1+V32 -> 5 | X32: =1+W32 -> 6 | Y32: =1+X32 -> 7 | Z32: =1+Y32 -> 8 | AA32: =1+Z32 -> 9 | ... AK32: =1+AJ32 -> 19 | AL32: >=20
O33: Annual resolutions (left y-axis) | Q33: Resolutions | S33: =S39 -> 472 | T33: =T39 -> 267 | U33: =U39 -> 244 | V33: =V39 -> 235 | W33: =W39 -> 144 | X33: =X39 -> 91 | Y33: =Y39 -> 66 | Z33: =Z39 -> 50 | ... AK33: =AK39 -> 8 | AL33: =AM33-SUM(S33:AK33) -> 30 | AM33: =+R39 -> 1801
O34: Cumulative % resolved (right y-axis) | Q34: % resolved | S34: =SUM($S33:S33)/$AM$33 -> 0.26207662 | T34: =SUM($S33:T33)/$AM$33 -> 0.4103276 | U34: =SUM($S33:U33)/$AM$33 -> 0.54580788 | V34: =SUM($S33:V33)/$AM$33 -> 0.67629095 | W34: =SUM($S33:W33)/$AM$33 -> 0.75624653 | X34: =SUM($S33:X33)/$AM$33 -> 0.80677401 | Y34: =SUM($S33:Y33)/$AM$33 -> 0.84342032 | Z34: =SUM($S33:Z33)/$AM$33 -> 0.87118268 | ... AL34: =SUM($S33:AL33)/$AM$33 -> 1
S38: 1 | T38: 2 | U38: 3 | V38: 4 | W38: 5 | X38: 6 | Y38: 7 | Z38: 8 | AA38: 9 | AB38: 10 | AC38: 11 | AD38: 12 | AE38: 13 | AF38: 14 | AG38: 15 | AH38: 16 | AI38: 17 | AJ38: 18 | AK38: 19 | AL38: 20 | AM38: 21 | AN38: 22 | AO38: 23 | AP38: 24 | AQ38: 25 | AR38: 26 | AS38: 27 | AT38: 28 | AU38: 29 | AV38: 30 | AW38: 31 | AX38: 32 | AY38: 33 | AZ38: 34 | BA38: 35 | BB38: 36 | BC38: 37 | BD38: 38 | BE38: 39 | BF38: 40
R39: =C43 -> 1801 | S39: =IFERROR(HLOOKUP(S$38,$Q$42:$BF$43,2,FALSE),0) -> 472 | T39: =IFERROR(HLOOKUP(T$38,$Q$42:$BF$43,2,FALSE),0) -> 267 | U39: =IFERROR(HLOOKUP(U$38,$Q$42:$BF$43,2,FALSE),0) -> 244 | V39: =IFERROR(HLOOKUP(V$38,$Q$42:$BF$43,2,FALSE),0) -> 235 | W39: =IFERROR(HLOOKUP(W$38,$Q$42:$BF$43,2,FALSE),0) -> 144 | X39: =IFERROR(HLOOKUP(X$38,$Q$42:$BF$43,2,FALSE),0) -> 91 | Y39: =IFERROR(HLOOKUP(Y$38,$Q$42:$BF$43,2,FALSE),0) -> 66 | Z39: =IFERROR(HLOOKUP(Z$38,$Q$42:$BF$43,2,FALSE),0) -> 50 | ... BF39: =IFERROR(HLOOKUP(BF$38,$Q$42:$BF$43,2,FALSE),0) -> 0
A42: year_submission | B42: cod_category_ctp | C42: CountOfid_contract1 | Q42: 1 | R42: 2 | S42: 3 | T42: 4 | U42: 5 | V42: 6 | W42: 7 | X42: 8 | Y42: 9 | Z42: 10 | AA42: 11 | AB42: 12 | AC42: 13 | AD42: 14 | AE42: 15 | AF42: 16 | AG42: 17 | AH42: 18 | AI42: 19 | AJ42: 20 | AK42: 0 | AL42: 0 | AM42: 0 | AN42: 0 | AO42: 0 | AP42: 0 | AQ42: 0 | AR42: 0 | AS42: 0 | AT42: 0 | AU42: 0 | AV42: 0 | AW42: 0 | AX42: 0 | AY42: 0 | AZ42: 0 | BA42: 0 | BB42: 0 | BC42: 0 | BD42: 0 | BE42: 0 | BF42: 0
A43: 2024 | B43: Private | C43: 1801 | Q43: 472 | R43: 267 | S43: 244 | T43: 235 | U43: 144 | V43: 91 | W43: 66 | X43: 50 | Y43: 60 | Z43: 33 | AA43: 26 | AB43: 22 | AC43: 19 | AD43: 10 | AE43: 8 | AF43: 6 | AG43: 5 | AH43: 5 | AI43: 8 | AJ43: 30 | AK43: 0 | AL43: 0 | AM43: 0 | AN43: 0 | AO43: 0 | AP43: 0 | AQ43: 0 | AR43: 0 | AS43: 0 | AT43: 0 | AU43: 0 | AV43: 0 | AW43: 0 | AX43: 0 | AY43: 0 | AZ43: 0 | BA43: 0 | BB43: 0 | BC43: 0 | BD43: 0 | BE43: 0 | BF43: 0
Q44: =Q33 -> Resolutions
Q45: =Q34 -> % resolved

Sheet CTP_Info
B3: Table 3: Dataset composition
B5: Item | C5: Count
B6: Counterparts | C6: 10476
B7: Contracts | C7: 15507
B8: Countries | C8: 158
B9: Defaulted counterparts | C9: =+DR!E5 -> 2101
B10: Defaulted Contracts | C10: 2401
B11: Contracts for recovery rates | C11: =+RR!C5 -> 1801
B13: Figure 7: Active counterparts for observation period

Sheet DR_TtD_GICS
F2: Table 6: Time to default – GICS sectors
F4: GICS sector | G4: Number of defaults
G5: Total | H5: Time of default (years after signature)
H6: 0 | I6: 1 | J6: 2 | K6: 3 | L6: 4 | M6: 5 | N6: 6 | O6: 7 | P6: 8 | Q6: 9 | R6: 10 | S6: 11 | T6: 12 | U6: 13 | V6: 14 | W6: 15 | X6: 16 | Y6: 17 | Z6: 18 | AA6: 19 | AB6: >=20
F7: Administration
F8: Communication services | G8: 61 | H8: 2 | I8: 15 | J8: 10 | K8: 13 | L8: 6 | M8: 4 | N8: 4 | O8: 3 | P8: 2 | Q8: 0 | R8: 0 | S8: 0 | T8: 2 | U8: 0 | V8: 0 | W8: 0 | X8: 0 | Y8: 0 | Z8: 0 | AA8: 0 | AB8: 0
F9: Consumer discretionary | G9: 247 | H9: 10 | I9: 35 | J9: 56 | K9: 33 | L9: 30 | M9: 23 | N9: 23 | O9: 8 | P9: 14 | Q9: 7 | R9: 2 | S9: 3 | T9: 1 | U9: 0 | V9: 1 | W9: 0 | X9: 0 | Y9: 1 | Z9: 0 | AA9: 0 | AB9: 0
F10: Consumer staples | G10: 385 | H10: 24 | I10: 67 | J10: 81 | K10: 81 | L10: 46 | M10: 39 | N10: 19 | O10: 8 | P10: 6 | Q10: 2 | R10: 6 | S10: 2 | T10: 0 | U10: 1 | V10: 0 | W10: 2 | X10: 1 | Y10: 0 | Z10: 0 | AA10: 0 | AB10: 0
F11: Energy | G11: 47 | H11: 1 | I11: 9 | J11: 12 | K11: 8 | L11: 4 | M11: 5 | N11: 4 | O11: 1 | P11: 0 | Q11: 0 | R11: 1 | S11: 0 | T11: 0 | U11: 2 | V11: 0 | W11: 0 | X11: 0 | Y11: 0 | Z11: 0 | AA11: 0 | AB11: 0
F12: Financials | G12: 552 | H12: 67 | I12: 98 | J12: 104 | K12: 102 | L12: 60 | M12: 37 | N12: 29 | O12: 15 | P12: 21 | Q12: 5 | R12: 2 | S12: 2 | T12: 4 | U12: 3 | V12: 2 | W12: 1 | X12: 0 | Y12: 0 | Z12: 0 | AA12: 0 | AB12: 0
F13: Health care | G13: 75 | H13: 1 | I13: 11 | J13: 16 | K13: 16 | L13: 13 | M13: 4 | N13: 4 | O13: 4 | P13: 2 | Q13: 0 | R13: 3 | S13: 1 | T13: 0 | U13: 0 | V13: 0 | W13: 0 | X13: 0 | Y13: 0 | Z13: 0 | AA13: 0 | AB13: 0
F14: Industrials | G14: 170 | H14: 11 | I14: 25 | J14: 33 | K14: 34 | L14: 22 | M14: 11 | N14: 14 | O14: 6 | P14: 4 | Q14: 3 | R14: 1 | S14: 1 | T14: 1 | U14: 2 | V14: 1 | W14: 0 | X14: 1 | Y14: 0 | Z14: 0 | AA14: 0 | AB14: 0
F15: Information technology
F16: Materials | G16: 240 | H16: 12 | I16: 31 | J16: 52 | K16: 35 | L16: 20 | M16: 20 | N16: 18 | O16: 16 | P16: 15 | Q16: 6 | R16: 7 | S16: 2 | T16: 2 | U16: 0 | V16: 3 | W16: 0 | X16: 1 | Y16: 0 | Z16: 0 | AA16: 0 | AB16: 0
F17: Real estate | G17: 40 | H17: 0 | I17: 6 | J17: 10 | K17: 8 | L17: 6 | M17: 4 | N17: 3 | O17: 1 | P17: 1 | Q17: 1 | R17: 0 | S17: 0 | T17: 0 | U17: 0 | V17: 0 | W17: 0 | X17: 0 | Y17: 0 | Z17: 0 | AA17: 0 | AB17: 0
F18: Utilities | G18: 303 | H18: 21 | I18: 39 | J18: 63 | K18: 54 | L18: 37 | M18: 22 | N18: 20 | O18: 9 | P18: 12 | Q18: 8 | R18: 7 | S18: 2 | T18: 7 | U18: 1 | V18: 0 | W18: 1 | X18: 0 | Y18: 0 | Z18: 0 | AA18: 0 | AB18: 0
F19: Others | G19: 270 | H19: 12 | I19: 33 | J19: 41 | K19: 32 | L19: 28 | M19: 23 | N19: 23 | O19: 18 | P19: 14 | Q19: 15 | R19: 4 | S19: 7 | T19: 5 | U19: 6 | V19: 2 | W19: 1 | X19: 3 | Y19: 0 | Z19: 0 | AA19: 0 | AB19: 3
F20: All sectors | G20: 2401 | H20: 162 | I20: 371 | J20: 479 | K20: 419 | L20: 273 | M20: 193 | N20: 161 | O20: 89 | P20: 92 | Q20: 48 | R20: 33 | S20: 20 | T20: 22 | U20: 15 | V20: 9 | W20: 5 | X20: 6 | Y20: 1 | Z20: 0 | AA20: 0 | AB20: 3
F22: GICS sector | G22: Total defaults | H22: Percentage of total defaults (cumulative)
H23: Time of default (years after signature)
H24: 0 | I24: 1 | J24: 2 | K24: 3 | L24: 4 | M24: 5 | N24: 6 | O24: 7 | P24: 8 | Q24: 9 | R24: 10 | S24: 11 | T24: 12 | U24: 13 | V24: 14 | W24: 15 | X24: 16 | Y24: 17 | Z24: 18 | AA24: 19 | AB24: >=20
F25: Administration
F26: Communication services | G26: 61 | H26: 0.032786885 | I26: 0.27868852 | J26: 0.44262295 | K26: 0.6557377 | L26: 0.75409836 | M26: 0.81967213 | N26: 0.8852459 | O26: 0.93442623 | P26: 0.96721311 | Q26: 0.96721311 | R26: 0.96721311 | S26: 0.96721311 | T26: 1 | U26: 1 | V26: 1 | W26: 1 | X26: 1 | Y26: 1 | Z26: 1 | AA26: 1 | AB26: 1
F27: Consumer discretionary | G27: 247 | H27: 0.04048583 | I27: 0.18218623 | J27: 0.40890688 | K27: 0.54251012 | L27: 0.66396761 | M27: 0.75708502 | N27: 0.85020243 | O27: 0.88259109 | P27: 0.93927126 | Q27: 0.96761134 | R27: 0.9757085 | S27: 0.98785425 | T27: 0.99190283 | U27: 0.99190283 | V27: 0.99595142 | W27: 0.99595142 | X27: 0.99595142 | Y27: 1 | Z27: 1 | AA27: 1 | AB27: 1
F28: Consumer staples | G28: 385 | H28: 0.062337662 | I28: 0.23636364 | J28: 0.44675325 | K28: 0.65714286 | L28: 0.77662338 | M28: 0.87792208 | N28: 0.92727273 | O28: 0.94805195 | P28: 0.96363636 | Q28: 0.96883117 | R28: 0.98441558 | S28: 0.98961039 | T28: 0.98961039 | U28: 0.99220779 | V28: 0.99220779 | W28: 0.9974026 | X28: 1 | Y28: 1 | Z28: 1 | AA28: 1 | AB28: 1
F29: Energy | G29: 47 | H29: 0.021276596 | I29: 0.21276596 | J29: 0.46808511 | K29: 0.63829787 | L29: 0.72340426 | M29: 0.82978723 | N29: 0.91489362 | O29: 0.93617021 | P29: 0.93617021 | Q29: 0.93617021 | R29: 0.95744681 | S29: 0.95744681 | T29: 0.95744681 | U29: 1 | V29: 1 | W29: 1 | X29: 1 | Y29: 1 | Z29: 1 | AA29: 1 | AB29: 1
F30: Financials | G30: 552 | H30: 0.12137681 | I30: 0.29891304 | J30: 0.48731884 | K30: 0.67210145 | L30: 0.7807971 | M30: 0.84782609 | N30: 0.90036232 | O30: 0.92753623 | P30: 0.96557971 | Q30: 0.97463768 | R30: 0.97826087 | S30: 0.98188406 | T30: 0.98913043 | U30: 0.99456522 | V30: 0.99818841 | W30: 1 | X30: 1 | Y30: 1 | Z30: 1 | AA30: 1 | AB30: 1
F31: Health care | G31: 75 | H31: 0.013333333 | I31: 0.16 | J31: 0.37333333 | K31: 0.58666667 | L31: 0.76 | M31: 0.81333333 | N31: 0.86666667 | O31: 0.92 | P31: 0.94666667 | Q31: 0.94666667 | R31: 0.98666667 | S31: 1 | T31: 1 | U31: 1 | V31: 1 | W31: 1 | X31: 1 | Y31: 1 | Z31: 1 | AA31: 1 | AB31: 1
F32: Industrials | G32: 170 | H32: 0.064705882 | I32: 0.21176471 | J32: 0.40588235 | K32: 0.60588235 | L32: 0.73529412 | M32: 0.8 | N32: 0.88235294 | O32: 0.91764706 | P32: 0.94117647 | Q32: 0.95882353 | R32: 0.96470588 | S32: 0.97058824 | T32: 0.97647059 | U32: 0.98823529 | V32: 0.99411765 | W32: 0.99411765 | X32: 1 | Y32: 1 | Z32: 1 | AA32: 1 | AB32: 1
F33: Information technology
F34: Materials | G34: 240 | H34: 0.05 | I34: 0.17916667 | J34: 0.39583333 | K34: 0.54166667 | L34: 0.625 | M34: 0.70833333 | N34: 0.78333333 | O34: 0.85 | P34: 0.9125 | Q34: 0.9375 | R34: 0.96666667 | S34: 0.975 | T34: 0.98333333 | U34: 0.98333333 | V34: 0.99583333 | W34: 0.99583333 | X34: 1 | Y34: 1 | Z34: 1 | AA34: 1 | AB34: 1
F35: Real estate | G35: 40 | H35: 0 | I35: 0.15 | J35: 0.4 | K35: 0.6 | L35: 0.75 | M35: 0.85 | N35: 0.925 | O35: 0.95 | P35: 0.975 | Q35: 1 | R35: 1 | S35: 1 | T35: 1 | U35: 1 | V35: 1 | W35: 1 | X35: 1 | Y35: 1 | Z35: 1 | AA35: 1 | AB35: 1
F36: Utilities | G36: 303 | H36: 0.069306931 | I36: 0.1980198 | J36: 0.40594059 | K36: 0.58415842 | L36: 0.70627063 | M36: 0.77887789 | N36: 0.84488449 | O36: 0.87458746 | P36: 0.91419142 | Q36: 0.94059406 | R36: 0.96369637 | S36: 0.97029703 | T36: 0.99339934 | U36: 0.99669967 | V36: 0.99669967 | W36: 1 | X36: 1 | Y36: 1 | Z36: 1 | AA36: 1 | AB36: 1
F37: Others | G37: 270 | H37: 0.044444444 | I37: 0.16666667 | J37: 0.31851852 | K37: 0.43703704 | L37: 0.54074074 | M37: 0.62592593 | N37: 0.71111111 | O37: 0.77777778 | P37: 0.82962963 | Q37: 0.88518519 | R37: 0.9 | S37: 0.92592593 | T37: 0.94444444 | U37: 0.96666667 | V37: 0.97407407 | W37: 0.97777778 | X37: 0.98888889 | Y37: 0.98888889 | Z37: 0.98888889 | AA37: 0.98888889 | AB37: 1
F38: All sectors | G38: 2401 | H38: 0.067471887 | I38: 0.22199084 | J38: 0.42149105 | K38: 0.59600167 | L38: 0.70970429 | M38: 0.79008746 | N38: 0.85714286 | O38: 0.89421075 | P38: 0.93252811 | Q38: 0.95251978 | R38: 0.96626406 | S38: 0.97459392 | T38: 0.98375677 | U38: 0.99000416 | V38: 0.9937526 | W38: 0.99583507 | X38: 0.99833403 | Y38: 0.99875052 | Z38: 0.99875052 | AA38: 0.99875052 | AB38: 1
B66: 5850

Sheet DR_TtD_Reg
F2: Table 5: Time to default – regions
F4: Region | G4: Number of defaults
G5: Total | H5: Time of default (years after signature)
H6: 0 | I6: 1 | J6: 2 | K6: 3 | L6: 4 | M6: 5 | N6: 6 | O6: 7 | P6: 8 | Q6: 9 | R6: 10 | S6: 11 | T6: 12 | U6: 13 | V6: 14 | W6: 15 | X6: 16 | Y6: 17 | Z6: 18 | AA6: 19 | AB6: >=20
F7: East Asia & Pacific | G7: 189 | H7: 6 | I7: 34 | J7: 50 | K7: 29 | L7: 22 | M7: 18 | N7: 18 | O7: 5 | P7: 5 | Q7: 1 | R7: 1 | S7: 0 | T7: 0 | U7: 0 | V7: 0 | W7: 0 | X7: 0 | Y7: 0 | Z7: 0 | AA7: 0 | AB7: 0
F8: Europe & Central Asia | G8: 657 | H8: 41 | I8: 124 | J8: 150 | K8: 136 | L8: 76 | M8: 59 | N8: 24 | O8: 15 | P8: 15 | Q8: 9 | R8: 2 | S8: 0 | T8: 2 | U8: 1 | V8: 1 | W8: 1 | X8: 1 | Y8: 0 | Z8: 0 | AA8: 0 | AB8: 0
F9: Latin America & Caribbean | G9: 400 | H9: 19 | I9: 57 | J9: 72 | K9: 67 | L9: 52 | M9: 30 | N9: 29 | O9: 20 | P9: 20 | Q9: 10 | R9: 7 | S9: 5 | T9: 4 | U9: 2 | V9: 1 | W9: 1 | X9: 2 | Y9: 0 | Z9: 1 | AA9: 1 | AB9: 0
F10: Middle East & North Africa | G10: 175 | H10: 5 | I10: 17 | J10: 27 | K10: 29 | L10: 14 | M10: 15 | N10: 9 | O10: 16 | P10: 11 | Q10: 1 | R10: 3 | S10: 5 | T10: 7 | U10: 9 | V10: 3 | W10: 1 | X10: 1 | Y10: 1 | Z10: 1 | AA10: 0 | AB10: 0
F11: South Asia | G11: 153 | H11: 8 | I11: 18 | J11: 27 | K11: 19 | L11: 22 | M11: 18 | N11: 13 | O11: 10 | P11: 4 | Q11: 5 | R11: 3 | S11: 3 | T11: 2 | U11: 1 | V11: 0 | W11: 0 | X11: 0 | Y11: 0 | Z11: 0 | AA11: 0 | AB11: 0
F12: Sub-Saharan Africa | G12: 780 | H12: 78 | I12: 113 | J12: 141 | K12: 130 | L12: 82 | M12: 52 | N12: 66 | O12: 20 | P12: 36 | Q12: 22 | R12: 16 | S12: 7 | T12: 7 | U12: 2 | V12: 4 | W12: 2 | X12: 2 | Y12: 0 | Z12: 0 | AA12: 0 | AB12: 0
F13: Other | G13: 47 | H13: 5 | I13: 8 | J13: 12 | K13: 9 | L13: 5 | M13: 1 | N13: 2 | O13: 3 | P13: 1 | Q13: 0 | R13: 1 | S13: 0 | T13: 0 | U13: 0 | V13: 0 | W13: 0 | X13: 0 | Y13: 0 | Z13: 0 | AA13: 0 | AB13: 0
F14: All regions | G14: 2401 | H14: 162 | I14: 371 | J14: 479 | K14: 419 | L14: 273 | M14: 193 | N14: 161 | O14: 89 | P14: 92 | Q14: 48 | R14: 33 | S14: 20 | T14: 22 | U14: 15 | V14: 9 | W14: 5 | X14: 6 | Y14: 1 | Z14: 0 | AA14: 0 | AB14: 3
F16: Region | G16: Total defaults | H16: Percentage of total defaults (cumulative)
H17: Time of default (years after signature)
H18: 0 | I18: 1 | J18: 2 | K18: 3 | L18: 4 | M18: 5 | N18: 6 | O18: 7 | P18: 8 | Q18: 9 | R18: 10 | S18: 11 | T18: 12 | U18: 13 | V18: 14 | W18: 15 | X18: 16 | Y18: 17 | Z18: 18 | AA18: 19 | AB18: >=20
F19: East Asia & Pacific | G19: 189 | H19: 0.031746032 | I19: 0.21164021 | J19: 0.47619048 | K19: 0.62962963 | L19: 0.74603175 | M19: 0.84126984 | N19: 0.93650794 | O19: 0.96296296 | P19: 0.98941799 | Q19: 0.99470899 | R19: 1 | S19: 1 | T19: 1 | U19: 1 | V19: 1 | W19: 1 | X19: 1 | Y19: 1 | Z19: 1 | AA19: 1 | AB19: 1
F20: Europe & Central Asia | G20: 657 | H20: 0.062404871 | I20: 0.25114155 | J20: 0.47945205 | K20: 0.68645358 | L20: 0.8021309 | M20: 0.89193303 | N20: 0.92846271 | O20: 0.95129376 | P20: 0.97412481 | Q20: 0.98782344 | R20: 0.99086758 | S20: 0.99086758 | T20: 0.99391172 | U20: 0.99543379 | V20: 0.99695586 | W20: 0.99847793 | X20: 1 | Y20: 1 | Z20: 1 | AA20: 1 | AB20: 1
F21: Latin America & Caribbean | G21: 400 | H21: 0.0475 | I21: 0.19 | J21: 0.37 | K21: 0.5375 | L21: 0.6675 | M21: 0.7425 | N21: 0.815 | O21: 0.865 | P21: 0.915 | Q21: 0.94 | R21: 0.9575 | S21: 0.97 | T21: 0.98 | U21: 0.985 | V21: 0.9875 | W21: 0.99 | X21: 0.995 | Y21: 0.995 | Z21: 0.9975 | AA21: 1 | AB21: 1
F22: Middle East & North Africa | G22: 175 | H22: 0.028571429 | I22: 0.12571429 | J22: 0.28 | K22: 0.44571429 | L22: 0.52571429 | M22: 0.61142857 | N22: 0.66285714 | O22: 0.75428571 | P22: 0.81714286 | Q22: 0.82285714 | R22: 0.84 | S22: 0.86857143 | T22: 0.90857143 | U22: 0.96 | V22: 0.97714286 | W22: 0.98285714 | X22: 0.98857143 | Y22: 0.99428571 | Z22: 1 | AA22: 1 | AB22: 1
F23: South Asia | G23: 153 | H23: 0.052287582 | I23: 0.16993464 | J23: 0.34640523 | K23: 0.47058824 | L23: 0.61437908 | M23: 0.73202614 | N23: 0.81699346 | O23: 0.88235294 | P23: 0.90849673 | Q23: 0.94117647 | R23: 0.96078431 | S23: 0.98039216 | T23: 0.99346405 | U23: 1 | V23: 1 | W23: 1 | X23: 1 | Y23: 1 | Z23: 1 | AA23: 1 | AB23: 1
F24: Sub-Saharan Africa | G24: 780 | H24: 0.1 | I24: 0.24487179 | J24: 0.42564103 | K24: 0.59230769 | L24: 0.6974359 | M24: 0.76410256 | N24: 0.84871795 | O24: 0.87435897 | P24: 0.92051282 | Q24: 0.94871795 | R24: 0.96923077 | S24: 0.97820513 | T24: 0.98717949 | U24: 0.98974359 | V24: 0.99487179 | W24: 0.9974359 | X24: 1 | Y24: 1 | Z24: 1 | AA24: 1 | AB24: 1
F25: Other | G25: 47 | H25: 0.10638298 | I25: 0.27659574 | J25: 0.53191489 | K25: 0.72340426 | L25: 0.82978723 | M25: 0.85106383 | N25: 0.89361702 | O25: 0.95744681 | P25: 0.9787234 | Q25: 0.9787234 | R25: 1 | S25: 1 | T25: 1 | U25: 1 | V25: 1 | W25: 1 | X25: 1 | Y25: 1 | Z25: 1 | AA25: 1 | AB25: 1
F26: All regions | G26: 2401 | H26: 0.067471887 | I26: 0.22199084 | J26: 0.42149105 | K26: 0.59600167 | L26: 0.70970429 | M26: 0.79008746 | N26: 0.85714286 | O26: 0.89421075 | P26: 0.93252811 | Q26: 0.95251978 | R26: 0.96626406 | S26: 0.97459392 | T26: 0.98375677 | U26: 0.99000416 | V26: 0.9937526 | W26: 0.99583507 | X26: 0.99833403 | Y26: 0.99875052 | Z26: 0.99875052 | AA26: 0.99875052 | AB26: 1

Sheet DR_TtD_SecGrp
E1: Infrastructure + Renewables | F1: =SUM(F12,F10) -> 614 | G1: =SUM(G12,G10) -> 33 | H1: =SUM(H12,H10) -> 87 | I1: =SUM(I12,I10) -> 134 | J1: =SUM(J12,J10) -> 117 | K1: =SUM(K12,K10) -> 81 | L1: =SUM(L12,L10) -> 52 | M1: =SUM(M12,M10) -> 46 | ... AA1: =SUM(AA12,AA10) -> 0 | AD1: Infrastructure + Renewables | AP1: Total | AQ1: High Income | AR1: EMDE
E2: Table 7: Time to default – sector groupings | G2: =G1/$F1 -> 0.053745928 | H2: =H1/$F1+G2 -> 0.19543974 | I2: =I1/$F1+H2 -> 0.41368078 | J2: =J1/$F1+I2 -> 0.60423453 | K2: =K1/$F1+J2 -> 0.73615635 | L2: =L1/$F1+K2 -> 0.82084691 | M2: =M1/$F1+L2 -> 0.89576547 | N2: =N1/$F1+M2 -> 0.9218241 | O2: =O1/$F1+N2 -> 0.95276873 | ... AA2: =AA1/$F1+Z2 -> 1 | AD2: Median equivalent | AE2: =$I$6*(50%-I2)/(J2-I2)+$J$6*(J2-50%)/(J2-I2) -> 2.5470085
AD3: Average default rte | AE3: =DR_SecGrp_Year!G2 -> 0.034220779 | AP3: =DR_Inc!$M$13 -> 0.031291857 | AQ3: =DR_Inc!I8 -> 0.018888585 | AR3: =DR_Inc!I14 -> 0.033850067
E4: Sector groupings | F4: Number of defaults | AD4: Cumul. default density | AE4: =G2/$Q2 -> 0.054455446 | AF4: =H2/$Q2 -> 0.1980198 | AG4: =I2/$Q2 -> 0.41914191 | AH4: =J2/$Q2 -> 0.61221122 | AI4: =K2/$Q2 -> 0.74587459 | AJ4: =L2/$Q2 -> 0.83168317 | AK4: =M2/$Q2 -> 0.90759076 | AL4: =N2/$Q2 -> 0.9339934 | ... AN4: =P2/$Q2 -> 0.99339934
F5: Total | G5: Time of default (years after signature) | AD5: Estimated default term structure | AE5: 1 | AF5: 2 | AG5: 3 | AH5: 4 | AI5: 5 | AJ5: 6 | AK5: 7 | AL5: 8 | AM5: 9 | AN5: 10
G6: 0 | H6: 1 | I6: 2 | J6: 3 | K6: 4 | L6: 5 | M6: 6 | N6: 7 | O6: 8 | P6: 9 | Q6: 10 | R6: 11 | S6: 12 | T6: 13 | U6: 14 | V6: 15 | W6: 16 | X6: 17 | Y6: 18 | Z6: 19 | AA6: >=20 | AE6: =$AE3*(1+(AE4-50%)) -> 0.018973897 | AF6: =$AE3*(1+(AF4-50%)) -> 0.023886782 | AG6: =$AE3*(1+(AG4-50%)) -> 0.031453753 | AH6: =$AE3*(1+(AH4-50%)) -> 0.038060735 | AI6: =$AE3*(1+(AI4-50%)) -> 0.042634799 | AJ6: =$AE3*(1+(AJ4-50%)) -> 0.045571236 | AK6: =$AE3*(1+(AK4-50%)) -> 0.048168853 | AL6: =$AE3*(1+(AL4-50%)) -> 0.049072372 | ... AN6: =$AE3*(1+(AN4-50%)) -> 0.051105289
E7: Financial institutions | F7: 552 | G7: 67 | H7: 98 | I7: 104 | J7: 102 | K7: 60 | L7: 37 | M7: 29 | N7: 15 | O7: 21 | P7: 5 | Q7: 2 | R7: 2 | S7: 4 | T7: 3 | U7: 2 | V7: 1 | W7: 0 | X7: 0 | Y7: 0 | Z7: 0 | AA7: 0 | AD7: High income | AE7: =$AQ$3/$AP$3*AE6 -> 0.011453142 | AF7: =$AQ$3/$AP$3*AF6 -> 0.014418687 | AG7: =$AQ$3/$AP$3*AG6 -> 0.018986309 | AH7: =$AQ$3/$AP$3*AH6 -> 0.022974457 | AI7: =$AQ$3/$AP$3*AI6 -> 0.025735482 | AJ7: =$AQ$3/$AP$3*AJ6 -> 0.027507992 | AK7: =$AQ$3/$AP$3*AK6 -> 0.029075981 | AL7: =$AQ$3/$AP$3*AL6 -> 0.029621369 | ... AN7: =$AQ$3/$AP$3*AN6 -> 0.030848491
E8: Non-financial institutions | F8: 1849 | G8: 95 | H8: 273 | I8: 375 | J8: 317 | K8: 213 | L8: 156 | M8: 132 | N8: 74 | O8: 71 | P8: 43 | Q8: 31 | R8: 18 | S8: 18 | T8: 12 | U8: 7 | V8: 4 | W8: 6 | X8: 1 | Y8: 0 | Z8: 0 | AA8: 3 | AD8: EMDE | AE8: =$AR$3/$AP$3*AE6 -> 0.020525075 | AF8: =$AR$3/$AP$3*AF6 -> 0.025839603 | AG8: =$AR$3/$AP$3*AG6 -> 0.034025198 | AH8: =$AR$3/$AP$3*AH6 -> 0.041172322 | AI8: =$AR$3/$AP$3*AI6 -> 0.046120331 | AJ8: =$AR$3/$AP$3*AJ6 -> 0.049296831 | AK8: =$AR$3/$AP$3*AK6 -> 0.052106812 | AL8: =$AR$3/$AP$3*AL6 -> 0.053084196 | ... AN8: =$AR$3/$AP$3*AN6 -> 0.055283311
E9: Banking | F9: 398 | G9: 59 | H9: 68 | I9: 69 | J9: 76 | K9: 41 | L9: 26 | M9: 23 | N9: 11 | O9: 15 | P9: 3 | Q9: 1 | R9: 0 | S9: 3 | T9: 2 | U9: 1 | V9: 0 | W9: 0 | X9: 0 | Y9: 0 | Z9: 0 | AA9: 0
E10: Infrastructure | F10: 429 | G10: 22 | H10: 62 | I10: 91 | J10: 83 | K10: 55 | L10: 36 | M10: 34 | N10: 13 | O10: 13 | P10: 10 | Q10: 3 | R10: 1 | S10: 4 | T10: 2 | U10: 0 | V10: 0 | W10: 0 | X10: 0 | Y10: 0 | Z10: 0 | AA10: 0 | AD10: Infrastructure
E11: Non-bank financials | F11: 154 | G11: 8 | H11: 30 | I11: 35 | J11: 26 | K11: 19 | L11: 11 | M11: 6 | N11: 4 | O11: 6 | P11: 2 | Q11: 1 | R11: 2 | S11: 1 | T11: 1 | U11: 1 | V11: 1 | W11: 0 | X11: 0 | Y11: 0 | Z11: 0 | AA11: 0 | AD11: Median equivalent | AE11: =$I$6*(50%-I22)/(J22-I22)+$J$6*(J22-50%)/(J22-I22) -> 2.5240964
E12: Renewables | F12: 185 | G12: 11 | H12: 25 | I12: 43 | J12: 34 | K12: 26 | L12: 16 | M12: 12 | N12: 3 | O12: 6 | P12: 7 | Q12: 1 | R12: 0 | S12: 1 | T12: 0 | U12: 0 | V12: 0 | W12: 0 | X12: 0 | Y12: 0 | Z12: 0 | AA12: 0 | AD12: Average default rte | AE12: =DR_SecGrp_Year!G10 -> 0.035991938
E13: Services | F13: 185 | G13: 9 | H13: 33 | I13: 36 | J13: 29 | K13: 25 | L13: 16 | M13: 14 | N13: 7 | O13: 5 | P13: 1 | Q13: 0 | R13: 2 | S13: 2 | T13: 2 | U13: 2 | V13: 1 | W13: 1 | X13: 0 | Y13: 0 | Z13: 0 | AA13: 0 | AD13: Cumul. default density | AE13: =G22/$Q22 -> 0.052132701 | AF13: =H22/$Q22 -> 0.19905213 | AG13: =I22/$Q22 -> 0.41469194 | AH13: =J22/$Q22 -> 0.61137441 | AI13: =K22/$Q22 -> 0.74170616 | AJ13: =L22/$Q22 -> 0.82701422 | AK13: =M22/$Q22 -> 0.90758294 | AL13: =N22/$Q22 -> 0.93838863 | ... AN13: =P22/$Q22 -> 0.992891
E14: All sectors* | F14: 2401 | G14: 162 | H14: 371 | I14: 479 | J14: 419 | K14: 273 | L14: 193 | M14: 161 | N14: 89 | O14: 92 | P14: 48 | Q14: 33 | R14: 20 | S14: 22 | T14: 15 | U14: 9 | V14: 5 | W14: 6 | X14: 1 | Y14: 0 | Z14: 0 | AA14: 3 | AD14: Estimated default term structure | AE14: 1 | AF14: 2 | AG14: 3 | AH14: 4 | AI14: 5 | AJ14: 6 | AK14: 7 | AL14: 8 | AM14: 9 | AN14: 10
AE15: =$AE12*(1+(AE13-50%)) -> 0.019872326 | AF15: =$AE12*(1+(AF13-50%)) -> 0.025160241 | AG15: =$AE12*(1+(AG13-50%)) -> 0.032921536 | AH15: =$AE12*(1+(AH13-50%)) -> 0.040000519 | AI15: =$AE12*(1+(AI13-50%)) -> 0.044691411 | AJ15: =$AE12*(1+(AJ13-50%)) -> 0.047761813 | AK15: =$AE12*(1+(AK13-50%)) -> 0.050661638 | AL15: =$AE12*(1+(AL13-50%)) -> 0.051770394 | ... AN15: =$AE12*(1+(AN13-50%)) -> 0.05373204
E16: Sector groupings | F16: Total defaults | G16: Percentage of total defaults (cumulative) | AD16: High income | AE16: =$AQ$3/$AP$3*AE15 -> 0.011995456 | AF16: =$AQ$3/$AP$3*AF15 -> 0.015187381 | AG16: =$AQ$3/$AP$3*AG15 -> 0.019872301 | AH16: =$AQ$3/$AP$3*AH15 -> 0.024145361 | AI16: =$AQ$3/$AP$3*AI15 -> 0.026976906 | AJ16: =$AQ$3/$AP$3*AJ15 -> 0.028830282 | AK16: =$AQ$3/$AP$3*AK15 -> 0.030580692 | AL16: =$AQ$3/$AP$3*AL15 -> 0.031249966 | ... AN16: =$AQ$3/$AP$3*AN15 -> 0.032434067
G17: Time of default (years after signature) | AD17: EMDE | AE17: =$AR$3/$AP$3*AE15 -> 0.021496953 | AF17: =$AR$3/$AP$3*AF15 -> 0.027217172 | AG17: =$AR$3/$AP$3*AG15 -> 0.035612977 | AH17: =$AR$3/$AP$3*AH15 -> 0.04327069 | AI17: =$AR$3/$AP$3*AI15 -> 0.048345078 | AJ17: =$AR$3/$AP$3*AJ15 -> 0.051666495 | AK17: =$AR$3/$AP$3*AK15 -> 0.05480339 | AL17: =$AR$3/$AP$3*AL15 -> 0.056002791 | ... AN17: =$AR$3/$AP$3*AN15 -> 0.058124807
G18: 0 | H18: 1 | I18: 2 | J18: 3 | K18: 4 | L18: 5 | M18: 6 | N18: 7 | O18: 8 | P18: 9 | Q18: 10 | R18: 11 | S18: 12 | T18: 13 | U18: 14 | V18: 15 | W18: 16 | X18: 17 | Y18: 18 | Z18: 19 | AA18: >=20
E19: Financial institutions | F19: 552 | G19: 0.12137681 | H19: 0.29891304 | I19: 0.48731884 | J19: 0.67210145 | K19: 0.7807971 | L19: 0.84782609 | M19: 0.90036232 | N19: 0.92753623 | O19: 0.96557971 | P19: 0.97463768 | Q19: 0.97826087 | R19: 0.98188406 | S19: 0.98913043 | T19: 0.99456522 | U19: 0.99818841 | V19: 1 | W19: 1 | X19: 1 | Y19: 1 | Z19: 1 | AA19: 1 | AD19: Renewables
E20: Non-financial institutions | F20: 1849 | G20: 0.051379124 | H20: 0.1990265 | I20: 0.40183883 | J20: 0.57328286 | K20: 0.68848026 | L20: 0.77285019 | M20: 0.84424013 | N20: 0.88426176 | O20: 0.9226609 | P20: 0.94591671 | Q20: 0.96268253 | R20: 0.97241752 | S20: 0.98215251 | T20: 0.98864251 | U20: 0.99242834 | V20: 0.99459167 | W20: 0.99783667 | X20: 0.9983775 | Y20: 0.9983775 | Z20: 0.9983775 | AA20: 1 | AD20: Median equivalent | AE20: =$I$6*(50%-I24)/(J24-I24)+$J$6*(J24-50%)/(J24-I24) -> 2.6029412
E21: Banking | F21: 398 | G21: 0.14824121 | H21: 0.31909548 | I21: 0.49246231 | J21: 0.68341709 | K21: 0.78643216 | L21: 0.85175879 | M21: 0.90954774 | N21: 0.93718593 | O21: 0.97487437 | P21: 0.98241206 | Q21: 0.98492462 | R21: 0.98492462 | S21: 0.99246231 | T21: 0.99748744 | U21: 1 | V21: 1 | W21: 1 | X21: 1 | Y21: 1 | Z21: 1 | AA21: 1 | AD21: Average default rte | AE21: =DR_SecGrp_Year!I10 -> 0.030515961
E22: Infrastructure | F22: 429 | G22: 0.051282051 | H22: 0.1958042 | I22: 0.40792541 | J22: 0.6013986 | K22: 0.72960373 | L22: 0.81351981 | M22: 0.89277389 | N22: 0.92307692 | O22: 0.95337995 | P22: 0.97668998 | Q22: 0.98368298 | R22: 0.98601399 | S22: 0.995338 | T22: 1 | U22: 1 | V22: 1 | W22: 1 | X22: 1 | Y22: 1 | Z22: 1 | AA22: 1 | AD22: Cumul. default density | AE22: =G24/$Q24 -> 0.059782609 | AF22: =H24/$Q24 -> 0.19565217 | AG22: =I24/$Q24 -> 0.42934783 | AH22: =J24/$Q24 -> 0.61413043 | AI22: =K24/$Q24 -> 0.75543478 | AJ22: =L24/$Q24 -> 0.8423913 | AK22: =M24/$Q24 -> 0.9076087 | AL22: =N24/$Q24 -> 0.92391304 | ... AN22: =P24/$Q24 -> 0.99456522
E23: Non-bank financials | F23: 154 | G23: 0.051948052 | H23: 0.24675325 | I23: 0.47402597 | J23: 0.64285714 | K23: 0.76623377 | L23: 0.83766234 | M23: 0.87662338 | N23: 0.9025974 | O23: 0.94155844 | P23: 0.95454545 | Q23: 0.96103896 | R23: 0.97402597 | S23: 0.98051948 | T23: 0.98701299 | U23: 0.99350649 | V23: 1 | W23: 1 | X23: 1 | Y23: 1 | Z23: 1 | AA23: 1 | AD23: Estimated default term structure | AE23: 1 | AF23: 2 | AG23: 3 | AH23: 4 | AI23: 5 | AJ23: 6 | AK23: 7 | AL23: 8 | AM23: 9 | AN23: 10
E24: Renewables | F24: 185 | G24: 0.059459459 | H24: 0.19459459 | I24: 0.42702703 | J24: 0.61081081 | K24: 0.75135135 | L24: 0.83783784 | M24: 0.9027027 | N24: 0.91891892 | O24: 0.95135135 | P24: 0.98918919 | Q24: 0.99459459 | R24: 0.99459459 | S24: 1 | T24: 1 | U24: 1 | V24: 1 | W24: 1 | X24: 1 | Y24: 1 | Z24: 1 | AA24: 1 | AE24: =$AE21*(1+(AE22-50%)) -> 0.017082304 | AF24: =$AE21*(1+(AF22-50%)) -> 0.021228494 | AG24: =$AE21*(1+(AG22-50%)) -> 0.028359942 | AH24: =$AE21*(1+(AH22-50%)) -> 0.033998761 | AI24: =$AE21*(1+(AI22-50%)) -> 0.038310798 | AJ24: =$AE21*(1+(AJ22-50%)) -> 0.04096436 | AK24: =$AE21*(1+(AK22-50%)) -> 0.042954532 | AL24: =$AE21*(1+(AL22-50%)) -> 0.043452074 | ... AN24: =$AE21*(1+(AN22-50%)) -> 0.045608093
E25: Services | F25: 185 | G25: 0.048648649 | H25: 0.22702703 | I25: 0.42162162 | J25: 0.57837838 | K25: 0.71351351 | L25: 0.8 | M25: 0.87567568 | N25: 0.91351351 | O25: 0.94054054 | P25: 0.94594595 | Q25: 0.94594595 | R25: 0.95675676 | S25: 0.96756757 | T25: 0.97837838 | U25: 0.98918919 | V25: 0.99459459 | W25: 1 | X25: 1 | Y25: 1 | Z25: 1 | AA25: 1 | AD25: High income | AE25: =$AQ$3/$AP$3*AE24 -> 0.010311326 | AF25: =$AQ$3/$AP$3*AF24 -> 0.012814075 | AG25: =$AQ$3/$AP$3*AG24 -> 0.017118804 | AH25: =$AQ$3/$AP$3*AH24 -> 0.020522543 | AI25: =$AQ$3/$AP$3*AI24 -> 0.023125402 | AJ25: =$AQ$3/$AP$3*AJ24 -> 0.024727161 | AK25: =$AQ$3/$AP$3*AK24 -> 0.025928481 | AL25: =$AQ$3/$AP$3*AL24 -> 0.02622881 | ... AN25: =$AQ$3/$AP$3*AN24 -> 0.02753024
E26: All sectors* | F26: 2401 | G26: 0.067471887 | H26: 0.22199084 | I26: 0.42149105 | J26: 0.59600167 | K26: 0.70970429 | L26: 0.79008746 | M26: 0.85714286 | N26: 0.89421075 | O26: 0.93252811 | P26: 0.95251978 | Q26: 0.96626406 | R26: 0.97459392 | S26: 0.98375677 | T26: 0.99000416 | U26: 0.9937526 | V26: 0.99583507 | W26: 0.99833403 | X26: 0.99875052 | Y26: 0.99875052 | Z26: 0.99875052 | AA26: 1 | AD26: EMDE | AE26: =$AR$3/$AP$3*AE24 -> 0.018478837 | AF26: =$AR$3/$AP$3*AF24 -> 0.022963992 | AG26: =$AR$3/$AP$3*AG24 -> 0.030678458 | AH26: =$AR$3/$AP$3*AH24 -> 0.036778269 | AI26: =$AR$3/$AP$3*AI24 -> 0.04144283 | AJ26: =$AR$3/$AP$3*AJ24 -> 0.044313329 | AK26: =$AR$3/$AP$3*AK24 -> 0.046466203 | AL26: =$AR$3/$AP$3*AL24 -> 0.047004422 | ... AN26: =$AR$3/$AP$3*AN24 -> 0.049336702
E28: *Note: The sum of the individual groupings exceeds the total as counterparties can be part of multiple groups | AD28: ALL
AD29: Median equivalent | AE29: =$I$6*(50%-I33)/(J33-I33)+$J$6*(J33-50%)/(J33-I33) -> #DIV/0!
AD30: Average default rte | AE30: =DR_GICS!I21 -> 0.035393609
AD31: Cumul. default density | AE31: =G26/$Q26 -> 0.069827586 | AF31: =H26/$Q26 -> 0.22974138 | AG31: =I26/$Q26 -> 0.4362069 | AH31: =J26/$Q26 -> 0.61681034 | AI31: =K26/$Q26 -> 0.73448276 | AJ31: =L26/$Q26 -> 0.81767241 | AK31: =M26/$Q26 -> 0.88706897 | AL31: =N26/$Q26 -> 0.92543103 | ... AN31: =P26/$Q26 -> 0.98577586
AD32: Estimated default term structure | AE32: 1 | AF32: 2 | AG32: 3 | AH32: 4 | AI32: 5 | AJ32: 6 | AK32: 7 | AL32: 8 | AM32: 9 | AN32: 10
AE33: =$AE30*(1+(AE31-50%)) -> 0.020168255 | AF33: =$AE30*(1+(AF31-50%)) -> 0.025828181 | AG33: =$AE30*(1+(AG31-50%)) -> 0.03313574 | AH33: =$AE30*(1+(AH31-50%)) -> 0.039527948 | AI33: =$AE30*(1+(AI31-50%)) -> 0.0436928 | AJ33: =$AE30*(1+(AJ31-50%)) -> 0.046637182 | AK33: =$AE30*(1+(AK31-50%)) -> 0.049093376 | AL33: =$AE30*(1+(AL31-50%)) -> 0.050451148 | ... AN33: =$AE30*(1+(AN31-50%)) -> 0.052586969
AD34: High income | AE34: =$AQ$3/$AP$3*AE33 -> 0.012174087 | AF34: =$AQ$3/$AP$3*AF33 -> 0.015590567 | AG34: =$AQ$3/$AP$3*AG33 -> 0.020001601 | AH34: =$AQ$3/$AP$3*AH33 -> 0.023860105 | AI34: =$AQ$3/$AP$3*AI33 -> 0.026374118 | AJ34: =$AQ$3/$AP$3*AJ33 -> 0.028151425 | AK34: =$AQ$3/$AP$3*AK33 -> 0.029634048 | AL34: =$AQ$3/$AP$3*AL33 -> 0.030453635 | ... AN34: =$AQ$3/$AP$3*AN33 -> 0.031742872
AD35: EMDE | AE35: =$AR$3/$AP$3*AE33 -> 0.021817074 | AF35: =$AR$3/$AP$3*AF33 -> 0.027939718 | AG35: =$AR$3/$AP$3*AG33 -> 0.035844694 | AH35: =$AR$3/$AP$3*AH33 -> 0.042759485 | AI35: =$AR$3/$AP$3*AI33 -> 0.047264827 | AJ35: =$AR$3/$AP$3*AJ33 -> 0.050449922 | AK35: =$AR$3/$AP$3*AK33 -> 0.053106918 | AL35: =$AR$3/$AP$3*AL33 -> 0.054575692 | ... AN35: =$AR$3/$AP$3*AN33 -> 0.056886124

Sheet DR_Reg
I1: 90% confidence interval | J1: Average default rate
D2: 2 | E2: 4 | F2: 5 | G2: 6 | H2: 3 | I2: 15 | J2: 13 | K2: 16
D3: CTPs | E3: Years | F3: Defaults | G3: Observations | H3: Signed EUR Mn | I3: WLower | J3: WAvgDefRate | K3: WUpper
C5: Table 8: Default rates by World Bank region
C7: World Bank region | D7: Counter- parties | E7: Observed years | F7: Number of defaults | G7: Number of observations | H7: Signed amount € million | I7: =DR_GICS!H7 -> Lower of 90% confidence interval | J7: Average default rate | K7: =DR_GICS!J7 -> Upper of 90% confidence interval
C8: East Asia & Pacific | D8: 927 | E8: 31 | F8: 184 | G8: 4732 | H8: 41675.261 | I8: 0.028857068 | J8: 0.038884193 | K8: 0.048911318 | L8: =IF(ISERROR(K8),IF(M8="Grey",2,1),0) -> 0 | N8: East Asia & Pacific
C9: Europe & Central Asia | D9: 3543 | E9: 31 | F9: 573 | G9: 20888 | H9: 141719.33 | I9: 0.02287368 | J9: 0.027432018 | K9: 0.031990357 | L9: =IF(ISERROR(K9),IF(M9="Grey",2,1),0) -> 0 | M9: Grey | N9: Europe & Central Asia
C10: Latin America & Caribbean | D10: 2305 | E10: 31 | F10: 372 | G10: 12771 | H10: 94129.924 | I10: 0.022759132 | J10: 0.029128494 | K10: 0.035497857 | L10: =IF(ISERROR(K10),IF(M10="Grey",2,1),0) -> 0 | N10: Latin America & Caribbean
C11: Middle East & North Africa | D11: 704 | E11: 31 | F11: 148 | G11: 4361 | H11: 31100.473 | I11: 0.026116049 | J11: 0.03393717 | K11: 0.041758291 | L11: =IF(ISERROR(K11),IF(M11="Grey",2,1),0) -> 0 | M11: Grey | N11: Middle East & North Africa
C12: North America | D12: #N/A | E12: #N/A | F12: #N/A | G12: #N/A | H12: #N/A | I12: #N/A | J12: #N/A | K12: #N/A | L12: =IF(ISERROR(K12),IF(M12="Grey",2,1),0) -> 1 | N12: North America
C13: South Asia | D13: 898 | E13: 31 | F13: 158 | G13: 4823 | H13: 33901.537 | I13: 0.021954205 | J13: 0.032759693 | K13: 0.043565181 | L13: =IF(ISERROR(K13),IF(M13="Grey",2,1),0) -> 0 | N13: South Asia
C14: Sub-Saharan Africa | D14: 1800 | E14: 31 | F14: 626 | G14: 10348 | H14: 75299.38 | I14: 0.054642713 | J14: 0.060494782 | K14: 0.066346851 | L14: =IF(ISERROR(K14),IF(M14="Grey",2,1),0) -> 0 | M14: Grey | N14: Sub-Saharan Africa
C15: Multiple | D15: 299 | E15: 28 | F15: 40 | G15: 1438 | H15: 28534.941 | I15: 0.019220094 | J15: 0.027816412 | K15: 0.03641273 | L15: =IF(ISERROR(K15),IF(M15="Grey",2,1),0) -> 0 | N15: Other
C16: Overall, including omitted categories | D16: 10476 | E16: 31 | F16: 2101 | G16: 59361 | H16: 446360.85 | I16: 0.031889333 | J16: 0.035393609 | K16: 0.038897884
C18: Figure 8: Default rates by World Bank region

Sheet DR_Reg_Year
C2: Table 9: Annual default rates by World Bank region
C4: v | D4: East Asia & Pacific | E4: Europe & Central Asia | F4: Latin America & Caribbean | G4: Middle East & North Africa | H4: South Asia | I4: Sub-Saharan Africa
C6: Years | D6: 31 | E6: 31 | F6: 31 | G6: 31 | H6: 31 | I6: 31
C7: Counterparties | D7: 927 | E7: 3543 | F7: 2305 | G7: 704 | H7: 898 | I7: 1800
C8: Defaults | D8: 184 | E8: 573 | F8: 372 | G8: 148 | H8: 158 | I8: 626
C9: Observations | D9: 4732 | E9: 20888 | F9: 12771 | G9: 4361 | H9: 4823 | I9: 10348
C10: Average default rate | D10: 0.038884193 | E10: 0.027432018 | F10: 0.029128494 | G10: 0.03393717 | H10: 0.032759693 | I10: 0.060494782
C11: 1994 | D11: 0.023255814 | E11: 0.040816327 | F11: 0.010204082 | G11: 0.068965517 | H11: 0 | I11: 0.034482759
C12: 1995 | D12: 0.054545455 | E12: 0.030075188 | F12: 0.028436019 | G12: 0 | H12: 0 | I12: 0.056910569
C13: 1996 | D13: 0.015873016 | E13: 0.032258065 | F13: 0.0045045045 | G13: 0.071428571 | H13: 0 | I13: 0.015151515
C14: 1997 | D14: 0.04109589 | E14: 0.024752475 | F14: 0.021645022 | G14: 0 | H14: 0.061538462 | I14: 0.086330935
C15: 1998 | D15: 0.20779221 | E15: 0.059633028 | F15: 0.022624434 | G15: 0.023255814 | H15: 0.26760563 | I15: 0.094202899
C16: 1999 | D16: 0.041666667 | E16: 0.056 | F16: 0.017094017 | G16: 0.015151515 | H16: 0.018518519 | I16: 0.079710145
C17: 2000 | D17: 0.061728395 | E17: 0.04040404 | F17: 0.032258065 | G17: 0 | H17: 0.019230769 | I17: 0.079470199
C18: 2001 | D18: 0.083333333 | E18: 0.036809816 | F18: 0.032128514 | G18: 0.058823529 | H18: 0.076923077 | I18: 0.086206897
C19: 2002 | D19: 0.068493151 | E19: 0.023255814 | F19: 0.12643678 | G19: 0.14084507 | H19: 0.074074074 | I19: 0.085714286
C20: 2003 | D20: 0.14705882 | E20: 0.028497409 | F20: 0.11020408 | G20: 0.014492754 | H20: 0.0625 | I20: 0.08988764
C21: 2004 | D21: 0.125 | E21: 0 | F21: 0.046218487 | G21: 0.047619048 | H21: 0.14285714 | I21: 0.081967213
C22: 2005 | D22: 0.015625 | E22: 0.0038461538 | F22: 0.016460905 | G22: 0.048780488 | H22: 0.019230769 | I22: 0.12169312
... C41: 2024 | D41: 0.019736842 | E41: 0.01635514 | F41: 0.013280212 | G41: 0.01986755 | H41: 0.0029498525 | I41: 0.050964187

Sheet DR_Cont_Year
C2: Table 10: Annual default rates by continent
D4: Africa | E4: Asia | F4: Europe | G4: North America | H4: Oceania | I4: South America
C6: Years | D6: 31 | E6: 31 | F6: 31 | G6: 31 | H6: 31 | I6: 31
C7: Counterparties | D7: 2094 | E7: 2353 | F7: 3125 | G7: 1000 | H7: 37 | I7: 1210
C8: Defaults | D8: 667 | E8: 488 | F8: 491 | G8: 167 | H8: 6 | I8: 188
C9: Observations | D9: 12416 | E9: 12531 | F9: 18681 | G9: 5882 | H9: 192 | I9: 6483
C10: Average default rate | D10: 0.053721005 | E10: 0.03894342 | F10: 0.02628339 | G10: 0.028391704 | H10: 0.03125 | I10: 0.02899892
C11: 1994 | D11: 0.042857143 | E11: 0.010752688 | F11: 0.041666667 | G11: 0.017241379 | H11: 0 | I11: 0.0072463768
C12: 1995 | D12: 0.047297297 | E12: 0.025423729 | F12: 0.030769231 | G12: 0 | H12: 0 | I12: 0.04137931
C13: 1996 | D13: 0.019354839 | E13: 0.022556391 | F13: 0.033519553 | G13: 0 | H13: 0 | I13: 0.0065359477
C14: 1997 | D14: 0.074074074 | E14: 0.045454545 | F14: 0.026041667 | G14: 0.013513514 | H14: 0 | I14: 0.025477707
C15: 1998 | D15: 0.081761006 | E15: 0.21301775 | F15: 0.062801932 | G15: 0.029850746 | H15: 0 | I15: 0.019480519
C16: 1999 | D16: 0.071428571 | E16: 0.01875 | F16: 0.054852321 | G16: 0 | H16: 0.22222222 | I16: 0.025
C17: 2000 | D17: 0.06741573 | E17: 0.035502959 | F17: 0.039285714 | G17: 0.023255814 | H17: 0 | I17: 0.037267081
C18: 2001 | D18: 0.084158416 | E18: 0.067073171 | F18: 0.036065574 | G18: 0.048192771 | H18: 0.125 | I18: 0.024390244
C19: 2002 | D19: 0.086956522 | E19: 0.094674556 | F19: 0.025396825 | G19: 0.046511628 | H19: 0 | I19: 0.16860465
C20: 2003 | D20: 0.079439252 | E20: 0.090322581 | F20: 0.028248588 | G20: 0.098901099 | H20: 0 | I20: 0.11409396
C21: 2004 | D21: 0.064102564 | E21: 0.10738255 | F21: 0 | G21: 0.076086957 | H21: 0.25 | I21: 0.014388489
C22: 2005 | D22: 0.10121457 | E22: 0.025316456 | F22: 0.0042826552 | G22: 0.01010101 | H22: 0 | I22: 0.02189781
... C41: 2024 | D41: 0.040792541 | E41: 0.01543943 | F41: 0.01542777 | G41: 0.014792899 | H41: 0.25 | I41: 0.010695187

Sheet DR_GICS
H1: 90% confidence interval | I1: Average default rate
C2: 2 | D2: 4 | E2: 5 | F2: 6 | G2: 3 | H2: 15 | I2: 13 | J2: 16
C3: CTPs | D3: Years | E3: Defaults | F3: Observations | G3: Signed EUR Mn | H3: WLower | I3: WAvgDefRate | J3: WUpper
B5: Table 11: Default rates by GICS sector
B7: GICS Sector | C7: Counter- parties | D7: Observed years | E7: Number of defaults | F7: Number of observations | G7: Signed amount € million | H7: =DR!$H$4 -> Lower of 90% confidence interval | I7: Average default rate | J7: =DR!$J$4 -> Upper of 90% confidence interval
B8: Administration | K8: =IF(ISERROR(J8),IF(L8="Grey",2,1),0) -> 0 | M8: Administration
B9: Communication services | C9: 301 | D9: 31 | E9: 59 | F9: 1488 | G9: 12448.214 | H9: 0.030837345 | I9: 0.039650538 | J9: 0.04846373 | K9: =IF(ISERROR(J9),IF(L9="Grey",2,1),0) -> 0 | L9: Grey | M9: Communication services
B10: Consumer discretionary | C10: 843 | D10: 31 | E10: 258 | F10: 4331 | G10: 30631.565 | H10: 0.050306667 | I10: 0.059570538 | J10: 0.068834409 | K10: =IF(ISERROR(J10),IF(L10="Grey",2,1),0) -> 0 | M10: Consumer discretionary
B11: Consumer staples | C11: 1279 | D11: 31 | E11: 349 | F11: 6585 | G11: 32326.164 | H11: 0.046190929 | I11: 0.052999241 | J11: 0.059807553 | K11: =IF(ISERROR(J11),IF(L11="Grey",2,1),0) -> 0 | L11: Grey | M11: Consumer staples
B12: Energy | C12: 242 | D12: 31 | E12: 48 | F12: 1347 | G12: 15627.572 | H12: 0.027212806 | I12: 0.035634744 | J12: 0.044056682 | K12: =IF(ISERROR(J12),IF(L12="Grey",2,1),0) -> 0 | M12: Energy
B13: Financials | C13: 3788 | D13: 31 | E13: 520 | F13: 23045 | G13: 186887.85 | H13: 0.019395183 | I13: 0.022564548 | J13: 0.025733912 | K13: =IF(ISERROR(J13),IF(L13="Grey",2,1),0) -> 0 | L13: Grey | M13: Financials
B14: Health care | C14: 251 | D14: 31 | E14: 74 | F14: 1241 | G14: 7339.1729 | H14: 0.045798748 | I14: 0.059629331 | J14: 0.073459915 | K14: =IF(ISERROR(J14),IF(L14="Grey",2,1),0) -> 0 | M14: Health care
B15: Industrials | C15: 817 | D15: 31 | E15: 153 | F15: 4222 | G15: 53490.884 | H15: 0.029616965 | I15: 0.036238749 | J15: 0.042860534 | K15: =IF(ISERROR(J15),IF(L15="Grey",2,1),0) -> 0 | L15: Grey | M15: Industrials
B16: Information technology | C16: 62 | D16: 30 | E16: 14 | F16: 236 | G16: 2189.2193 | H16: 0.033163213 | I16: 0.059322034 | J16: 0.085480855 | K16: =IF(ISERROR(J16),IF(L16="Grey",2,1),0) -> 0 | M16: Information technology
B17: Materials | C17: 911 | D17: 31 | E17: 241 | F17: 5330 | G17: 30875.263 | H17: 0.038275758 | I17: 0.04521576 | J17: 0.052155761 | K17: =IF(ISERROR(J17),IF(L17="Grey",2,1),0) -> 0 | L17: Grey | M17: Materials
B18: Real estate | C18: 187 | D18: 31 | E18: 43 | F18: 862 | G18: 5851.9002 | H18: 0.039582866 | I18: 0.049883991 | J18: 0.060185115 | K18: =IF(ISERROR(J18),IF(L18="Grey",2,1),0) -> 0 | M18: Real estate
B19: Utilities | C19: 1390 | D19: 31 | E19: 255 | F19: 8633 | G19: 61550.887 | H19: 0.02515578 | I19: 0.02953782 | J19: 0.03391986 | K19: =IF(ISERROR(J19),IF(L19="Grey",2,1),0) -> 0 | L19: Grey | M19: Utilities
B20: Others | C20: 396 | D20: 31 | E20: 86 | F20: 1996 | G20: 7058.6561 | H20: 0.031483604 | I20: 0.043086172 | J20: 0.05468874 | K20: =IF(ISERROR(J20),IF(L20="Grey",2,1),0) -> 0 | M20: Others
B21: Overall, including omitted categories | C21: =DR!C5 -> 10476 | E21: =DR!E5 -> 2101 | F21: =DR!F5 -> 59361 | G21: =DR!G5 -> 446360.85 | H21: =DR!H5 -> 0.031889333 | I21: =DR!I5 -> 0.035393609 | J21: =DR!J5 -> 0.038897884
B23: Figure 9: Default rates by GICS sector

Sheet DR_GICS_Year
C2: Table 12: Annual default rates by GICS sector
D4: Administration | E4: Communication services | F4: Consumer discretionary | G4: Consumer staples | H4: Energy | I4: Financials | J4: Health care | K4: Industrials | L4: Information technology | M4: Materials | N4: Real estate | O4: Utilities | P4: Other
C6: Years | E6: 31 | F6: 31 | G6: 31 | H6: 31 | I6: 31 | J6: 31 | K6: 31 | L6: 30 | M6: 31 | N6: 31 | O6: 31 | P6: 31
C7: Counterparties | E7: 301 | F7: 843 | G7: 1279 | H7: 242 | I7: 3788 | J7: 251 | K7: 817 | L7: 62 | M7: 911 | N7: 187 | O7: 1390 | P7: 396
C8: Defaults | E8: 59 | F8: 258 | G8: 349 | H8: 48 | I8: 520 | J8: 74 | K8: 153 | L8: 14 | M8: 241 | N8: 43 | O8: 255 | P8: 86
C9: Observations | E9: 1488 | F9: 4331 | G9: 6585 | H9: 1347 | I9: 23045 | J9: 1241 | K9: 4222 | L9: 236 | M9: 5330 | N9: 862 | O9: 8633 | P9: 1996
C10: Average default rate | E10: 0.039650538 | F10: 0.059570538 | G10: 0.052999241 | H10: 0.035634744 | I10: 0.022564548 | J10: 0.059629331 | K10: 0.036238749 | L10: 0.059322034 | M10: 0.04521576 | N10: 0.049883991 | O10: 0.02953782 | P10: 0.043086172
C11: 1994 | E11: 0 | F11: 0.030612245 | G11: 0.028169014 | H11: 0 | I11: 0.010752688 | J11: 0 | K11: 0.058823529 | L11: 0 | M11: 0.031007752 | N11: 0 | O11: 0 | P11: 0.023255814
C12: 1995 | E12: 0 | F12: 0.03030303 | G12: 0.098765432 | H12: 0 | I12: 0 | J12: 0.14285714 | K12: 0 | L12: 0 | M12: 0.034965035 | N12: 0 | O12: 0.03125 | P12: 0.037735849
C13: 1996 | E13: 0 | F13: 0.038095238 | G13: 0.0125 | H13: 0 | I13: 0.012738854 | J13: 0.16666667 | K13: 0 | L13: 0 | M13: 0.0064516129 | N13: 0 | O13: 0.025641026 | P13: 0.053571429
C14: 1997 | E14: 0 | F14: 0.097087379 | G14: 0.088888889 | H14: 0 | I14: 0.010752688 | J14: 0 | K14: 0 | L14: 0 | M14: 0.04516129 | N14: 0 | O14: 0.042553191 | P14: 0
C15: 1998 | E15: 0 | F15: 0.13333333 | G15: 0.048543689 | H15: 0.08 | I15: 0.084158416 | J15: 0.5 | K15: 0.0625 | L15: 0 | M15: 0.10666667 | N15: 0 | O15: 0 | P15: 0.15517241
C16: 1999 | E16: 0.13333333 | F16: 0.0625 | G16: 0.052631579 | H16: 0.038461538 | I16: 0.03196347 | J16: 0.16666667 | K16: 0.020408163 | L16: 0 | M16: 0.026490066 | N16: 0 | O16: 0.016393443 | P16: 0.058823529
C17: 2000 | E17: 0.029411765 | F17: 0.075471698 | G17: 0.072 | H17: 0 | I17: 0.032258065 | J17: 0 | K17: 0.054545455 | L17: 0 | M17: 0.050632911 | N17: 0 | O17: 0 | P17: 0.01754386
C18: 2001 | E18: 0.058823529 | F18: 0.088235294 | G18: 0.056910569 | H18: 0.037037037 | I18: 0.038596491 | J18: 0.21428571 | K18: 0.050847458 | L18: 0 | M18: 0.045751634 | N18: 0 | O18: 0.013513514 | P18: 0.081967213
C19: 2002 | E19: 0.028571429 | F19: 0.18269231 | G19: 0.060344828 | H19: 0 | I19: 0.060897436 | J19: 0.125 | K19: 0.10714286 | L19: 0 | M19: 0.09375 | N19: 0.090909091 | O19: 0.076923077 | P19: 0
C20: 2003 | E20: 0.055555556 | F20: 0.10309278 | G20: 0.14285714 | H20: 0.058823529 | I20: 0.039156627 | J20: 0.1875 | K20: 0.086206897 | L20: 0.16666667 | M20: 0.054054054 | N20: 0 | O20: 0.092105263 | P20: 0
C21: 2004 | E21: 0.048780488 | F21: 0.043010753 | G21: 0.071428571 | H21: 0.1025641 | I21: 0.037940379 | J21: 0.055555556 | K21: 0.06557377 | L21: 0.42857143 | M21: 0.013513514 | N21: 0.066666667 | O21: 0 | P21: 0.013333333
C22: 2005 | E22: 0.071428571 | F22: 0.069306931 | G22: 0.050420168 | H22: 0.044444444 | I22: 0.01891253 | J22: 0.055555556 | K22: 0.029411765 | L22: 0 | M22: 0.017142857 | N22: 0 | O22: 0.037037037 | P22: 0
... C25: 2008 | E25: 0.053571429 | F25: 0.045454545 | G25: 0.062111801 | H25: 0.019607843 | I25: 0.026397516 | J25: 0 | K25: 0.045977011 | L25: 0 | M25: 0.025 | N25: 0 | O25: 0.02970297 | P25: 0.04
C26: 2009 | E26: 0.038461538 | F26: 0.051282051 | G26: 0.038251366 | H26: 0.036363636 | I26: 0.027624309 | J26: 0.03125 | K26: 0.07 | M26: 0.0625 | N26: 0 | O26: 0.015037594 | P26: 0.029411765
C27: 2010 | E27: 0 | F27: 0.085470085 | G27: 0.080188679 | H27: 0.017857143 | I27: 0.022546419 | J27: 0.055555556 | K27: 0.017699115 | L27: 0 | M27: 0.088235294 | N27: 0.1 | O27: 0.00625 | P27: 0.048780488
C28: 2011 | E28: 0.047058824 | F28: 0.0084033613 | G28: 0.036199095 | H28: 0.034482759 | I28: 0.017478152 | J28: 0.048780488 | K28: 0.078014184 | L28: 0 | M28: 0.03125 | N28: 0.0625 | O28: 0.021052632 | P28: 0.1
C29: 2012 | E29: 0.04494382 | F29: 0.060150376 | G29: 0.047826087 | H29: 0.01754386 | I29: 0.020594966 | J29: 0.045454545 | K29: 0.02 | L29: 0 | M29: 0.044554455 | N29: 0.10869565 | O29: 0.008583691 | P29: 0.054545455
C30: 2013 | E30: 0.025316456 | F30: 0.0375 | G30: 0.043650794 | H30: 0.046153846 | I30: 0.0055066079 | J30: 0.057692308 | K30: 0.022222222 | L30: 0 | M30: 0.027522936 | N30: 0.0625 | O30: 0.021126761 | P30: 0.051948052
C31: 2014 | E31: 0.03030303 | F31: 0.054545455 | G31: 0.037800687 | H31: 0.090909091 | I31: 0.014675052 | J31: 0.037037037 | K31: 0.072625698 | L31: 0.125 | M31: 0.083333333 | N31: 0.021276596 | O31: 0.038216561 | P31: 0.1
C32: 2015 | E32: 0.014705882 | F32: 0.034825871 | G32: 0.058651026 | H32: 0.084507042 | I32: 0.014503817 | J32: 0.057971014 | K32: 0.050847458 | L32: 0.090909091 | M32: 0.052083333 | N32: 0.021276596 | O32: 0.01627907 | P32: 0.021052632
